Workbook
Name CENTRO: LISTAS!$B$4:$B$41
Name CORES_BASE: LISTAS!$G$64:$G$81
Name DATABOOK: LISTAS!$E$4:$E$15
Name EQUIPO: LISTAS!$C$5:$C$7
Name ESPECIALIDADE: LISTAS!$K$4:$K$10
Name INSPECAO: LISTAS!$D$5:$D$10
Name OPCAO: LISTAS!$L$4:$L$5
Name PREPARO_DA_SUPERFICIE: LISTAS!$G$27:$G$32
Name PROJETISTA: LISTAS!$J$4:$J$18
Name TINTAS_DE_ACABAMENTO: LISTAS!$G$52:$G$61
Name TINTAS_DE_FUNDO: LISTAS!$G$34:$G$42
Name TINTAS_INTERMEDIARIA: LISTAS!$G$44:$G$50

Sheet CAPA
J1: LISTA DE CABOS | Y1: N° BRASKEM | AG1: REV.
Y2: BK-SP08-02000-LC-79-00001 | AG2: 1
J3: CÓDIGO DE PROJETO (PJ) | Y3: N° PROJETISTA | AG3: FOLHA
J4: PJ-1700281 | Y4: LI-CBE-25.248-529-0002_A 9048.E.LI.SAN.001-01 | AG4: 1 / 5
AG5: 1/2
J6: CENTRO LOGÍSTICO | S6: PLANTA | AA6: ÁREA
J7: SP08-PP3 | S7: SP08 | AA7: 02000
J8: TITULO DO PROJETO
J9: PP3-ADEQUAÇÕES PARA INSTALAÇÃO DE CALDEIRA ELÉTRICA
A33: LISTA DE CABOS ELÉTRICOS
A58: Rev. | C58: Data | F58: Codigo | H58: Descrição | Z58: Elaborado | AC58: Verificado | AF58: Aprovado
A59: 0 | C59: 46171 | F59: CO | H59: PARA COMENTÁRIOS, PJ-1700281, SANDECH | Z59: CCCM | AC59: VGAM | AF59: PMSS
A60: 1 | C60: 46211 | F60: CO | H60: PARA COMENTÁRIOS, PJ-1700281, SANDECH | Z60: CCCM | AC60: VGAM | AF60: PMSS
A66: Código de Emissão (Finalidade)
A67: PR | C67: Preliminary | G67: CO | I67: Para Comentário | M67: LE | O67: Liberado para Execução | U67: CC | W67: Conforme Construido
A68: AC | C68: Aceite Certif. | G68: PC | I68: Para Cotação | M68: LD | O68: Liberado para Det. | U68: CS | W68: Cancel./Substit.
A69: IN | C69: Informativo | G69: PP | I69: Para Compra | M69: CP | O69: Conforme Comprado | U69: CA | W69: Cancelado

Sheet FOLHA 2 
G1: LISTA DE CABOS | O1: N° BRASKEM | R1: REV.
O2: =CAPA!Y2 -> BK-SP08-02000-LC-79-00001 | R2: =CAPA!AG2 -> 1
G3: CÓDIGO DE PROJETO (PJ) | O3: N° PROJETISTA | R3: FOLHA
G4: PJ-1700281 | O4: LI-CBE-25.248-529-0002_A / 9048.E.LI.SAN.001-01 | R4: 2 / 5
G6: CENTRO LOGÍSTICO: | L6: ÁREA: | O6: PLANTA:
G7: SP08-PP3 | L7: SP08 | O7: 02000
G8: TITULO DO PROJETO
G9: PP3-ADEQUAÇÕES PARA INSTALAÇÃO DE CALDEIRA ELÉTRICA
A11: CABO (TAG DO CIRCUITO) | C11: DE | E11: TIPO | F11: COMPR. (m) | G11: FABRICANTE | I11: SEGURANÇA INTRÍNSECA | K11: BOBINA | L11: COMPR. TOTAL (m) | N11: PERCURSO | O11: DOCUMENTOS DE REFERÊNCIA | Q11: DESCRITIVO
C12: PARA (TAG FORNECEDOR/ COMBIO/ BRASKEM) | F12: CAPA EXT. (COR) | G12: MODELO | I12: CÓDIGO DE SUPRIMENTO | L12: COMPR. PARCIAL (m)
A13: CABOS DE BAIXA TENSÃO - 220 V
A14: LSB2001-MP2011-01F | C14: LSB-2001 | E14: 1x3/C#4 mm² | F14: 66 | G14: NOTA 1 | I14: NA | K14: BOBINA 1 | L14: 686 | N14: ELETROCENTRO > DESMI | O14: BK-SP08-02000-DI-70-00001 BK-SP08-02000-MC-74-00001 BK-SP08-02000-DP-71-00003 | Q14: BOMBA DOSADORA ELETROMAGNÉTICA DE HIPOCLORITO DE SÓDIO
C15: BD-10-01 / 42.MBD002 / MP2011 | F15: PRETA | G15: ISOLAÇÃO EPR 0,6/1kV 90°C | I15: - | L15: =F14 -> 66
A16: LSB2001-MP2012-01F | C16: LSB-2001 | E16: 1x3/C#4 mm² | F16: 66 | G16: NOTA 1 | I16: NA | K16: BOBINA 1 | L16: 686 | N16: ELETROCENTRO > DESMI | O16: BK-SP08-02000-DI-70-00001 BK-SP08-02000-MC-74-00001 BK-SP08-02000-DP-71-00003 | Q16: BOMBA DOSADORA ELETROMAGNÉTICA DE HIDRÓXIDO DE SÓDIO
C17: BD-11-01 / 42.MBD001 / MP2012 | F17: PRETA | G17: ISOLAÇÃO EPR 0,6/1kV 90°C | I17: - | L17: =F16 -> 66
A18: LSB2001-MP2013-01F | C18: LSB-2001 | E18: 1x3/C#4 mm² | F18: 66 | G18: NOTA 1 | I18: NA | K18: BOBINA 1 | L18: 686 | N18: ELETROCENTRO > DESMI | O18: BK-SP08-02000-DI-70-00001 BK-SP08-02000-MC-74-00001 BK-SP08-02000-DP-71-00003 | Q18: BOMBA DOSADORA ELETROMAGNÉTICA DE COAGULANTE
C19: BD-12-01 / 42.MBD003 / MP2013 | F19: PRETA | G19: ISOLAÇÃO EPR 0,6/1kV 90°C | I19: - | L19: =F18 -> 66
A20: LSB2001-MP2015-01F | C20: LSB-2001 | E20: 1x3/C#4 mm² | F20: 60 | G20: NOTA 1 | I20: NA | K20: BOBINA 1 | L20: 686 | N20: ELETROCENTRO > DESMI | O20: BK-SP08-02000-DI-70-00001 BK-SP08-02000-MC-74-00001 BK-SP08-02000-DP-71-00003 | Q20: BOMBA DOSADORA ELETROMAGNÉTICA DE ÁCIDO CLORÍDRICO (CEB)
C21: BD-51-01 / 42.MBD004 / MP2015 | F21: PRETA | G21: ISOLAÇÃO EPR 0,6/1kV 90°C | I21: - | L21: =F20 -> 60
A22: LSB2001-MP2016-01F | C22: LSB-2001 | E22: 1x3/C#4 mm² | F22: 60 | G22: NOTA 1 | I22: NA | K22: BOBINA 1 | L22: 686 | N22: ELETROCENTRO > DESMI | O22: BK-SP08-02000-DI-70-00001 BK-SP08-02000-MC-74-00001 BK-SP08-02000-DP-71-00003 | Q22: BOMBA DOSADORA ELETROMAGNÉTICA DE HIDRÓXIDO DE SÓDIO (CEB)
C23: BD-52-01 / 42.MBD005 / MP2016 | F23: PRETA | G23: ISOLAÇÃO EPR 0,6/1kV 90°C | I23: - | L23: =F22 -> 60
A24: LSB2001-MP2019-01F | C24: LSB-2001 | E24: 1x3/C#4 mm² | F24: 58 | G24: NOTA 1 | I24: NA | K24: BOBINA 1 | L24: 686 | N24: ELETROCENTRO > DESMI | O24: BK-SP08-02000-DI-70-00001 BK-SP08-02000-MC-74-00001 BK-SP08-02000-DP-71-00003 | Q24: BOMBA DOSADORA ELETROMAGNÉTICA DE CORREÇÃO DE PH
C25: BD-65-01 / 42.MBD007 / MP2019 | F25: PRETA | G25: ISOLAÇÃO EPR 0,6/1kV 90°C | I25: - | L25: =F24 -> 58
A26: LSB2001-MP2020-01F | C26: LSB-2001 | E26: 1x3/C#4 mm² | F26: 58 | G26: NOTA 1 | I26: NA | K26: BOBINA 1 | L26: 686 | N26: ELETROCENTRO > DESMI | O26: BK-SP08-02000-DI-70-00001 BK-SP08-02000-MC-74-00001 BK-SP08-02000-DP-71-00003 | Q26: BOMBA DOSADORA ELETROMAGNÉTICA DE BISSULFITO
C27: BD-66-01 / 42.MBD008 / MP2020 | F27: PRETA | G27: ISOLAÇÃO EPR 0,6/1kV 90°C | I27: - | L27: =F26 -> 58
A28: LSB2001-MP2021-01F | C28: LSB-2001 | E28: 1x3/C#4 mm² | F28: 58 | G28: NOTA 1 | I28: NA | K28: BOBINA 1 | L28: 686 | N28: ELETROCENTRO > DESMI | O28: BK-SP08-02000-DI-70-00001 BK-SP08-02000-MC-74-00001 BK-SP08-02000-DP-71-00003 | Q28: BOMBA DOSADORA ELETROMAGNÉTICA DE ANTI-INCRUSTANTE
C29: BD-67-01 / 42.MBD009 / MP2021 | F29: PRETA | G29: ISOLAÇÃO EPR 0,6/1kV 90°C | I29: - | L29: =F28 -> 58
A30: LSB2001-MP2022-01F | C30: LSB-2001 | E30: 1x3/C#4 mm² | F30: 58 | G30: NOTA 1 | I30: NA | K30: BOBINA 1 | L30: 686 | N30: ELETROCENTRO > DESMI | O30: BK-SP08-02000-DI-70-00001 BK-SP08-02000-MC-74-00001 BK-SP08-02000-DP-71-00003 | Q30: BOMBA DOSADORA ELETROMAGNÉTICA DE BIOCIDA
C31: BD-68-01 / 42.MBD010 / MP2022 | F31: PRETA | G31: ISOLAÇÃO EPR 0,6/1kV 90°C | I31: - | L31: =F30 -> 58
A32: LSB2001-01L | C32: LSB-2001 | E32: 1x3/C#4 mm² | F32: 95 | G32: NOTA 1 | I32: NA | K32: BOBINA 2 | L32: 707 | N32: ELETROCENTRO > ARRUAMENTO (ENTORNO DA UPV) | O32: BK-SP08-02000-DI-70-00001 BK-SP08-02000-MC-74-00001 BK-SP08-02000-DP-71-00001 | Q32: ILUMINAÇÃO DO ARRUAMENTO (ENTORNO DA UPV)
C33: 53.PN003-01L / LSB-2001-01L | F33: PRETA | G33: ISOLAÇÃO EPR 0,6/1kV 90°C | I33: - | L33: =F32 -> 95
A34: LSB2001-02L | C34: LSB-2001 | E34: 1x3/C#4 mm² | F34: 95 | G34: NOTA 1 | I34: NA | K34: BOBINA 2 | L34: 707 | N34: ELETROCENTRO > ARRUAMENTO (ENTORNO DA CALDEIRA) | O34: BK-SP08-02000-DI-70-00001 BK-SP08-02000-MC-74-00001 BK-SP08-02000-DP-71-00001 | Q34: ILUMINAÇÃO DO ARRUAMENTO (ENTORNO DA CALDEIRA)
C35: 53.PN003-02L / LSB-2001-02L | F35: PRETA | G35: ISOLAÇÃO EPR 0,6/1kV 90°C | I35: - | L35: =F34 -> 95
A36: LSB2001-03L | C36: LSB-2001 | E36: 1x3/C#4 mm² | F36: 84 | G36: NOTA 1 | I36: NA | K36: BOBINA 2 | L36: 707 | N36: ELETROCENTRO > CALDEIRA | O36: BK-SP08-02000-DI-70-00001 BK-SP08-02000-MC-74-00001 BK-SP08-02000-DP-71-00001 | Q36: ILUMINAÇÃO CALDEIRA
C37: 53.PN003-03L / LSB-2001-03L | F37: PRETA | G37: ISOLAÇÃO EPR 0,6/1kV 90°C | I37: - | L37: =F36 -> 84
A38: LSB2001-04L | C38: LSB-2001 | E38: 1x3/C#4 mm² | F38: 109 | G38: NOTA 1 | I38: NA | K38: BOBINA 2 | L38: 707 | N38: ELETROCENTRO > DESMI | O38: BK-SP08-02000-DI-70-00001 BK-SP08-02000-MC-74-00001 BK-SP08-02000-DP-71-00001 | Q38: ILUMINAÇÃO DESMI
C39: 53.PN003-04L / LSB-2001-04L | F39: PRETA | G39: ISOLAÇÃO EPR 0,6/1kV 90°C | I39: - | L39: =F38 -> 109
A40: LSB2001-05L | C40: LSB-2001 | E40: 1x3/C#4 mm² | F40: 74 | G40: NOTA 1 | I40: NA | K40: BOBINA 2 | L40: 707 | N40: ELETROCENTRO > DESAERADOR | O40: BK-SP08-02000-DI-70-00001 BK-SP08-02000-MC-74-00001 BK-SP08-02000-DP-71-00001 | Q40: ILUMINAÇÃO DESAERADOR
C41: 53.PN003-05L / LSB-2001-05L | F41: PRETA | G41: ISOLAÇÃO EPR 0,6/1kV 90°C | I41: - | L41: =F40 -> 74
A42: LSB2001-06L | C42: LSB-2001 | E42: 1x3/C#4 mm² | F42: 87 | G42: NOTA 1 | I42: NA | K42: BOBINA 2 | L42: 707 | N42: ELETROCENTRO > CALDEIRA | O42: BK-SP08-02000-DI-70-00001 BK-SP08-02000-MC-74-00001 BK-SP08-02000-DP-71-00001 | Q42: ILUMINAÇÃO EMERGÊNCIA CALDEIRA
...

Sheet FOLHA 3
G1: LISTA DE CABOS | O1: N° BRASKEM | R1: REV.
O2: =CAPA!Y2 -> BK-SP08-02000-LC-79-00001 | R2: =CAPA!AG2 -> 1
G3: CÓDIGO DE PROJETO (PJ) | O3: N° PROJETISTA | R3: FOLHA
G4: PJ-1700281 | O4: LI-CBE-25.248-529-0002_A / 9048.E.LI.SAN.001-01 | R4: 3 / 5
G6: CENTRO LOGÍSTICO: | L6: ÁREA: | O6: PLANTA:
G7: SP08-PP3 | L7: SP08 | O7: 02000
G8: TITULO DO PROJETO
G9: PP3-ADEQUAÇÕES PARA INSTALAÇÃO DE CALDEIRA ELÉTRICA
A11: CABO (TAG DO CIRCUITO) | C11: DE | E11: TIPO | F11: COMPR. (m) | G11: FABRICANTE | I11: SEGURANÇA INTRÍNSECA | K11: BOBINA | L11: COMPR. TOTAL (m) | N11: PERCURSO | O11: DOCUMENTOS DE REFERÊNCIA | Q11: DESCRITIVO
C12: PARA (TAG FORNECEDOR / COMBIO / BRASKEM) | F12: CAPA EXT. (COR) | G12: MODELO | I12: CÓDIGO DE SUPRIMENTO | L12: COMPR. PARCIAL (m)
A13: CABOS DE BAIXA TENSÃO - 220 V
A14: LSB2001-07L | C14: LSB-2001 | E14: 1x3/C#4 mm² | F14: 92 | G14: NOTA 1 | I14: NA | K14: BOBINA 2 | L14: 707 | N14: ELETROCENTRO > DESMI | O14: BK-SP08-02000-DI-70-00001 BK-SP08-02000-MC-74-00001 BK-SP08-02000-DP-71-00001 | Q14: ILUMINAÇÃO EMERGÊNCIA DESMI
C15: 53.PN003-07L / LSB-2001-07L | F15: PRETA | G15: ISOLAÇÃO EPR 0,6/1kV 90°C | I15: - | L15: =F14 -> 92
A16: LSB2001-08L | C16: LSB-2001 | E16: 1x3/C#4 mm² | F16: 71 | G16: NOTA 1 | I16: NA | K16: BOBINA 2 | L16: 707 | N16: ELETROCENTRO > DESAERADOR | O16: BK-SP08-02000-DI-70-00001 BK-SP08-02000-MC-74-00001 BK-SP08-02000-DP-71-00001 | Q16: ILUMINAÇÃO EMERGÊNCIA DESAERADOR
C17: 53.PN003-08L / LSB-2001-08L | F17: PRETA | G17: ISOLAÇÃO EPR 0,6/1kV 90°C | I17: - | L17: =F16 -> 71
A18: QD2001-PLC2002-01F | C18: QD-2001 | E18: 1x3/C#4 mm² | F18: 68 | G18: NOTA 1 | I18: NA | K18: BOBINA 1 | L18: 686 | N18: ELETROCENTRO > DESMI | O18: BK-SP08-02000-DI-70-00001 BK-SP08-02000-MC-74-00001 BK-SP08-02000-DP-71-00003 | Q18: PLC DESMI
C19: P-22-008 / 61.PN002 / PLC-20-02 | F19: PRETA | G19: ISOLAÇÃO EPR 0,6/1kV 90°C | I19: - | L19: =F18 -> 68
A20: QD2001-PLC2002-02F | C20: QD-2001 | E20: 1x3/C#4 mm² | F20: 68 | G20: NOTA 1 | I20: NA | K20: BOBINA 1 | L20: 686 | N20: ELETROCENTRO > DESMI | O20: BK-SP08-02000-DI-70-00001 BK-SP08-02000-MC-74-00001 BK-SP08-02000-DP-71-00003 | Q20: PLC DESMI (ALIMENTAÇÃO REDUNDANTE)
C21: P-22-008 / 61.PN002 / PLC-20-02 | F21: PRETA | G21: ISOLAÇÃO EPR 0,6/1kV 90°C | I21: - | L21: =F20 -> 68
A22: QDGT1STR-QD2001-01F | C22: QDG-T1STR | E22: 1x4/C#25 mm² | F22: 210 | G22: NOTA 1 | I22: NA | K22: BOBINA 7 | L22: 210 | N22: SS#1 > ELETROCENTRO | O22: BK-SP08-02000-DI-70-00001 BK-SP08-02000-MC-74-00001 BK-SP08-02000-DP-71-00003 | Q22: ALIMENTAÇÃO REDUNDANTE DO PAINEL DE ENERGIA ESTABILIZADA
C23: 53.PN004 / QD-2001 | F23: PRETA | G23: ISOLAÇÃO EPR 0,6/1kV 90°C | I23: - | L23: =F22 -> 210
A24: LSB2001-D2022-01F | C24: LSB-2001 | E24: 1x4/C#4 mm² | F24: 49 | G24: NOTA 1 | I24: NA | K24: BOBINA 3 | L24: 578 | N24: ELETROCENTRO > CALDEIRA | O24: BK-SP08-02000-DI-70-00001 BK-SP08-02000-MC-74-00001 BK-SP08-02000-DP-71-00003 | Q24: BOMBA DOSADORA 1 DE QUÍMICOS DA CALDEIRA
C25: DP401 / N/A / D2022 | F25: PRETA | G25: ISOLAÇÃO EPR 0,6/1kV 90°C | I25: - | L25: =F24 -> 49
A26: LSB2001-D2023-01F | C26: LSB-2001 | E26: 1x4/C#4 mm² | F26: 49 | G26: NOTA 1 | I26: NA | K26: BOBINA 3 | L26: 578 | N26: ELETROCENTRO > CALDEIRA | O26: BK-SP08-02000-DI-70-00001 BK-SP08-02000-MC-74-00001 BK-SP08-02000-DP-71-00003 | Q26: BOMBA DOSADORA 2 DE QUÍMICOS DA CALDEIRA
C27: DP402 / N/A / D2023 | F27: PRETA | G27: ISOLAÇÃO EPR 0,6/1kV 90°C | I27: - | L27: =F26 -> 49
A28: LSB2001-TS2001-01F | C28: LSB-2001 | E28: 1x4/C#10 mm² | F28: 42 | G28: NOTA 1 | I28: NA | K28: BOBINA 6 | L28: 146 | N28: ELETROCENTRO > CALDEIRA | O28: BK-SP08-02000-DI-70-00001 BK-SP08-02000-MC-74-00001 BK-SP08-02000-DP-71-00003 | Q28: TOMADAS PARA MANUTENÇÃO CALDEIRA
C29: 22.TOM001 / TS-2001 | F29: PRETA | G29: ISOLAÇÃO EPR 0,6/1kV 90°C | I29: - | L29: =F28 -> 42
A30: LSB2001-TS2002-01F | C30: LSB-2001 | E30: 1x4/C#10 mm² | F30: 52 | G30: NOTA 1 | I30: NA | K30: BOBINA 6 | L30: 146 | N30: ELETROCENTRO > DESAERADOR | O30: BK-SP08-02000-DI-70-00001 BK-SP08-02000-MC-74-00001 BK-SP08-02000-DP-71-00003 | Q30: TOMADAS PARA MANUTENÇÃO DESMI
C31: 22.TOM002 / TS-2002 | F31: PRETA | G31: ISOLAÇÃO EPR 0,6/1kV 90°C | I31: - | L31: =F30 -> 52
A32: CABOS DE BAIXA TENSÃO - 440 V
A33: CCM2001-MP2017-01F | C33: CCM-2001 | E33: 1x4/C#4 mm² | F33: 60 | G33: NOTA 1 | I33: NA | K33: BOBINA 3 | L33: 578 | N33: ELETROCENTRO > DESMI | O33: BK-SP08-02000-DI-70-00001 BK-SP08-02000-MC-74-00001 BK-SP08-02000-DP-71-00003 | Q33: BOMBA DOSADORA ELETROMECÂNICA DE HIPOCLORITO DE SÓDIO (CEB)
C34: BD-53-01 / 42.MBD006 / MP2017 | F34: PRETA | G34: ISOLAÇÃO EPR 0,6/1kV 90°C | I34: - | L34: =F33 -> 60
A35: CCM2001-MP2007-01F | C35: CCM-2001 | E35: 1x4/C#4 mm² | F35: 51 | G35: NOTA 1 | I35: NA | K35: BOBINA 3 | L35: 578 | N35: ELETROCENTRO > DESMI | O35: BK-SP08-02000-DI-70-00001 BK-SP08-02000-MC-74-00001 BK-SP08-02000-DP-71-00003 | Q35: BOMBA CENTRÍFUGA DE RECIRCULAÇÃO DE PERMEADO (PRINCIPAL)
C36: BC-90-01 / 42.MBC005A / MP2007 | F36: PRETA | G36: ISOLAÇÃO EPR 0,6/1kV 90°C | I36: - | L36: =F35 -> 51
A37: CCM2001-MP2010-01F | C37: CCM-2001 | E37: 1x4/C#4 mm² | F37: 51 | G37: NOTA 1 | I37: NA | K37: BOBINA 3 | L37: 578 | N37: ELETROCENTRO > DESMI | O37: BK-SP08-02000-DI-70-00001 BK-SP08-02000-MC-74-00001 BK-SP08-02000-DP-71-00003 | Q37: BOMBA CENTRÍFUGA DE RECIRCULAÇÃO DE PERMEADO (RESERVA)
C38: BC-90-02 / 42.MBC005B / MP2010 | F38: PRETA | G38: ISOLAÇÃO EPR 0,6/1kV 90°C | I38: - | L38: =F37 -> 51
A39: CCM2001-MP2014-01F | C39: CCM-2001 | E39: 1x4/C#4 mm² | F39: 55 | G39: NOTA 1 | I39: NA | K39: BOBINA 3 | L39: 578 | N39: ELETROCENTRO > DESMI | O39: BK-SP08-02000-DI-70-00001 BK-SP08-02000-MC-74-00001 BK-SP08-02000-DP-71-00003 | Q39: BOMBA CENTRÍFUGA DE CIP DA ULTRAFILTRAÇÃO
C40: BC-62-01 / 42.MBC002 / MP2014 | F40: PRETA | G40: ISOLAÇÃO EPR 0,6/1kV 90°C | I40: - | L40: =F39 -> 55
A41: CCM2001-MP2030-01F | C41: CCM-2001 | E41: 1x4/C#4 mm² | F41: 46 | G41: NOTA 1 | I41: NA | K41: BOBINA 3 | L41: 578 | N41: ELETROCENTRO > BOP | O41: BK-SP08-02000-DI-70-00001 BK-SP08-02000-MC-74-00001 BK-SP08-02000-DP-71-00003 | Q41: BOMBA DE EFLUENTE (BOP) (PRINCIPAL) NÃO CONTAMINADOS
C42: N/A / 42.MBC009A / MP2030 | F42: PRETA | G42: ISOLAÇÃO EPR 0,6/1kV 90°C | I42: - | L42: =F41 -> 46
...

Sheet FOLHA 4
G1: LISTA DE CABOS | O1: N° BRASKEM | R1: REV.
O2: =CAPA!Y2 -> BK-SP08-02000-LC-79-00001 | R2: =CAPA!AG2 -> 1
G3: CÓDIGO DE PROJETO (PJ) | O3: N° PROJETISTA | R3: FOLHA
G4: PJ-1700281 | O4: LI-CBE-25.248-529-0002_A / 9048.E.LI.SAN.001-01 | R4: 4 / 5
G6: CENTRO LOGÍSTICO: | L6: ÁREA: | O6: PLANTA:
G7: SP08-PP3 | L7: SP08 | O7: 02000
G8: TITULO DO PROJETO
G9: PP3-ADEQUAÇÕES PARA INSTALAÇÃO DE CALDEIRA ELÉTRICA
A11: CABO (TAG DO CIRCUITO) | C11: DE | E11: TIPO | F11: COMPR. (m) | G11: FABRICANTE | I11: SEGURANÇA INTRÍNSECA | K11: BOBINA | L11: COMPR. TOTAL (m) | N11: PERCURSO | O11: DOCUMENTOS DE REFERÊNCIA | Q11: DESCRITIVO
C12: PARA (TAG FORNECEDOR / COMBIO / BRASKEM) | F12: CAPA EXT. (COR) | G12: MODELO | I12: CÓDIGO DE SUPRIMENTO | L12: COMPR. PARCIAL (m)
A13: CABOS DE BAIXA TENSÃO - 440 V
A14: CCM2001-MP2018-01F | C14: CCM-2001 | E14: 1x4/C#4 mm² | F14: 55 | G14: NOTA 1 | I14: NA | K14: BOBINA 3 | L14: 578 | N14: ELETROCENTRO > DESMI | O14: BK-SP08-02000-DI-70-00001 BK-SP08-02000-MC-74-00001 BK-SP08-02000-DP-71-00003 | Q14: BOMBA CENTRÍFUGA DE LIMPEZA CIP
C15: BC-63-01 / 42.MBC006 / MP2018 | F15: PRETA | G15: ISOLAÇÃO EPR 0,6/1kV 90°C | I15: - | L15: =F14 -> 55
A16: CCM2001-MP2003-01F | C16: CCM-2001 | E16: 1x4/C#4 mm² | F16: 58 | G16: NOTA 1 | I16: NA | K16: BOBINA 3 | L16: 578 | N16: ELETROCENTRO > DESMI | O16: BK-SP08-02000-DI-70-00001 BK-SP08-02000-MC-74-00001 BK-SP08-02000-DP-71-00003 | Q16: BOMBA CENTRÍFUGA DE LAVAGEM DA ULTRAFILTRAÇÃO (PRINCIPAL)
C17: BC-72-01 / 42.MBC003A / MP2003 | F17: PRETA | G17: ISOLAÇÃO EPR 0,6/1kV 90°C | I17: - | L17: =F16 -> 58
A18: CCM2001-MP2004-01F | C18: CCM-2001 | E18: 1x4/C#4 mm² | F18: 58 | G18: NOTA 1 | I18: NA | K18: BOBINA 3 | L18: 578 | N18: ELETROCENTRO > DESMI | O18: BK-SP08-02000-DI-70-00001 BK-SP08-02000-MC-74-00001 BK-SP08-02000-DP-71-00003 | Q18: BOMBA CENTRÍFUGA DE LAVAGEM DA ULTRAFILTRAÇÃO (RESERVA)
C19: BC-72-02 / 42.MBC003B / MP2004 | F19: PRETA | G19: ISOLAÇÃO EPR 0,6/1kV 90°C | I19: - | L19: =F18 -> 58
A20: CCM2001-MP2001-01F | C20: CCM-2001 | E20: 1x4/C#4 mm² | F20: 71 | G20: NOTA 1 | I20: NA | K20: BOBINA 4 | L20: 555 | N20: ELETROCENTRO > DESMI | O20: BK-SP08-02000-DI-70-00001 BK-SP08-02000-MC-74-00001 BK-SP08-02000-DP-71-00003 | Q20: BOMBA CENTRÍFUGA DE ALIMENTAÇÃO DA ULTRAFILTRAÇÃO (PRINCIPAL)
C21: BC-70-01 / 42.MBC001A / MP2001 | F21: PRETA | G21: ISOLAÇÃO EPR 0,6/1kV 90°C | I21: - | L21: =F20 -> 71
A22: CCM2001-MP2002-01F | C22: CCM-2001 | E22: 1x4/C#4 mm² | F22: 71 | G22: NOTA 1 | I22: NA | K22: BOBINA 4 | L22: 555 | N22: ELETROCENTRO > DESMI | O22: BK-SP08-02000-DI-70-00001 BK-SP08-02000-MC-74-00001 BK-SP08-02000-DP-71-00003 | Q22: BOMBA CENTRÍFUGA DE ALIMENTAÇÃO DA ULTRAFILTRAÇÃO (RESERVA)
C23: BC-70-02 / 42.MBC001B / MP2002 | F23: PRETA | G23: ISOLAÇÃO EPR 0,6/1kV 90°C | I23: - | L23: =F22 -> 71
A24: CCM2001-MP2008-01F | C24: CCM-2001 | E24: 1x4/C#4 mm² | F24: 48 | G24: NOTA 1 | I24: NA | K24: BOBINA 4 | L24: 555 | N24: ELETROCENTRO > BOP | O24: BK-SP08-02000-DI-70-00001 BK-SP08-02000-MC-74-00001 BK-SP08-02000-DP-71-00003 | Q24: BOMBA DE AQUECIMENTO DESAERADOR (PRINCIPAL)
C25: BC-91-01 / 42.MBC007A / MP2008 | F25: PRETA | G25: ISOLAÇÃO EPR 0,6/1kV 90°C | I25: - | L25: =F24 -> 48
A26: CCM2001-MP2009-01F | C26: CCM-2001 | E26: 1x4/C#4 mm² | F26: 48 | G26: NOTA 1 | I26: NA | K26: BOBINA 4 | L26: 555 | N26: ELETROCENTRO > BOP | O26: BK-SP08-02000-DI-70-00001 BK-SP08-02000-MC-74-00001 BK-SP08-02000-DP-71-00003 | Q26: BOMBA DE AQUECIMENTO DESAERADOR (RESERVA)
C27: BC-91-02 / 42.MBC007B / MP2009 | F27: PRETA | G27: ISOLAÇÃO EPR 0,6/1kV 90°C | I27: - | L27: =F26 -> 48
A28: CCM2001-MP2005-01F | C28: CCM-2001 | E28: 1x4/C#4 mm² | F28: 60 | G28: NOTA 1 | I28: NA | K28: BOBINA 4 | L28: 555 | N28: ELETROCENTRO > DESMI | O28: BK-SP08-02000-DI-70-00001 BK-SP08-02000-MC-74-00001 BK-SP08-02000-DP-71-00003 | Q28: BOMBA DE ALIMENTAÇÃO DA OSMOSE REVERSA (PRINCIPAL)
C29: BC-73-01 / 42.MBC004A / MP2005 | F29: PRETA | G29: ISOLAÇÃO EPR 0,6/1kV 90°C | I29: - | L29: =F28 -> 60
A30: CCM2001-MP2006-01F | C30: CCM-2001 | E30: 1x4/C#4 mm² | F30: 60 | G30: NOTA 1 | I30: NA | K30: BOBINA 4 | L30: 555 | N30: ELETROCENTRO > DESMI | O30: BK-SP08-02000-DI-70-00001 BK-SP08-02000-MC-74-00001 BK-SP08-02000-DP-71-00003 | Q30: BOMBA DE ALIMENTAÇÃO DA OSMOSE REVERSA (RESERVA)
C31: BC-73-02 / 42.MBC004B / MP2006 | F31: PRETA | G31: ISOLAÇÃO EPR 0,6/1kV 90°C | I31: - | L31: =F30 -> 60
A32: CCM2001-MP2026-01F | C32: CCM-2001 | E32: 1x4/C#4 mm² | F32: 72 | G32: NOTA 1 | I32: NA | K32: BOBINA 4 | L32: 555 | N32: ELETROCENTRO > CALDEIRA | O32: BK-SP08-02000-DI-70-00001 BK-SP08-02000-MC-74-00001 BK-SP08-02000-DP-71-00003 | Q32: BOMBA DE CIRCULAÇÃO 1 (PRINCIPAL)
C33: CP301 / 22.MBC003 / MP2026 | F33: PRETA | G33: ISOLAÇÃO EPR 0,6/1kV 90°C | I33: - | L33: =F32 -> 72
A34: CCM2001-MP2027-01F | C34: CCM-2001 | E34: 1x4/C#4 mm² | F34: 72 | G34: NOTA 1 | I34: NA | K34: BOBINA 4 | L34: 555 | N34: ELETROCENTRO > CALDEIRA | O34: BK-SP08-02000-DI-70-00001 BK-SP08-02000-MC-74-00001 BK-SP08-02000-DP-71-00003 | Q34: BOMBA DE CIRCULAÇÃO 2 (RESERVA)
C35: CP302 / 22.MBC004 / MP2027 | F35: PRETA | G35: ISOLAÇÃO EPR 0,6/1kV 90°C | I35: - | L35: =F34 -> 72
A36: CCM2001-MP2024-01F | C36: CCM-2001 | E36: 1x4/C#6 mm² | F36: 42 | G36: NOTA 1 | I36: NA | K36: BOBINA 5 | L36: 84 | N36: ELETROCENTRO > CALDEIRA | O36: BK-SP08-02000-DI-70-00001 BK-SP08-02000-MC-74-00001 BK-SP08-02000-DP-71-00003 | Q36: BOMBA DE ÁGUA 1 (PRINCIPAL)
C37: FWP701 / 21.MBC001 / MP2024 | F37: PRETA | G37: ISOLAÇÃO EPR 0,6/1kV 90°C | I37: - | L37: =F36 -> 42
A38: CCM2001-MP2025-01F | C38: CCM-2001 | E38: 1x4/C#6 mm² | F38: 42 | G38: NOTA 1 | I38: NA | K38: BOBINA 5 | L38: 84 | N38: ELETROCENTRO > CALDEIRA | O38: BK-SP08-02000-DI-70-00001 BK-SP08-02000-MC-74-00001 BK-SP08-02000-DP-71-00003 | Q38: BOMBA DE ÁGUA 2 (RESERVA)
C39: FWP702 / 21.MBC002 / MP2025 | F39: PRETA | G39: ISOLAÇÃO EPR 0,6/1kV 90°C | I39: - | L39: =F38 -> 42
A40: CCM2001-MP2023-01F | C40: CCM-2001 | E40: 1x4/C#10 mm² | F40: 52 | G40: NOTA 1 | I40: NA | K40: BOBINA 6 | L40: 146 | N40: ELETROCENTRO > DESMI | O40: BK-SP08-02000-DI-70-00001 BK-SP08-02000-MC-74-00001 BK-SP08-02000-DP-71-00003 | Q40: BOMBA DE ALTA PRESSÃO DA OSMOSE REVERSA
C41: BC-28-01 / 42.MBC008 / MP2023 | F41: PRETA | G41: ISOLAÇÃO EPR 0,6/1kV 90°C | I41: - | L41: =F40 -> 52
A42: CCM2001-E2001-01F | C42: CCM-2001 | E42: 1x4/C#35 mm² | F42: 80 | G42: NOTA 1 | I42: NA | K42: BOBINA 8 | L42: 80 | N42: ELETROCENTRO > CALDEIRA | O42: BK-SP08-02000-DI-70-00001 BK-SP08-02000-MC-74-00001 BK-SP08-02000-DP-71-00003 | Q42: AQUECEDOR (STAND-BY)
...

Sheet FOLHA 5
G1: LISTA DE CABOS | O1: N° BRASKEM | R1: REV.
O2: =CAPA!Y2 -> BK-SP08-02000-LC-79-00001 | R2: =CAPA!AG2 -> 1
G3: CÓDIGO DE PROJETO (PJ) | O3: N° PROJETISTA | R3: FOLHA
G4: PJ-1700281 | O4: LI-CBE-25.248-529-0002_A / 9048.E.LI.SAN.001-01 | R4: 5 / 5
G6: CENTRO LOGÍSTICO: | L6: ÁREA: | O6: PLANTA:
G7: SP08-PP3 | L7: SP08 | O7: 02000
G8: TITULO DO PROJETO
G9: PP3-ADEQUAÇÕES PARA INSTALAÇÃO DE CALDEIRA ELÉTRICA
A11: CABO (TAG DO CIRCUITO) | C11: DE | E11: TIPO | F11: COMPR. (m) | G11: FABRICANTE | I11: SEGURANÇA INTRÍNSECA | K11: BOBINA | L11: COMPR. TOTAL (m) | N11: PERCURSO | O11: DOCUMENTOS DE REFERÊNCIA | Q11: DESCRITIVO
C12: PARA (TAG FORNECEDOR / COMBIO / BRASKEM) | F12: CAPA EXT. (COR) | G12: MODELO | I12: CÓDIGO DE SUPRIMENTO | L12: COMPR. PARCIAL (m)
A13: CABOS DE MÉDIA TENSÃO - 13,8 kV
A14: MVS1A/B-MVS2001-01F | C14: MVS1 A/B | E14: 3x1/C#185 mm² | F14: =175 -> 175 | G14: NOTA 1 | I14: NA | K14: BOBINA 9 / BOBINA 10 / BOBINA 11 | L14: 175 / 175 / 175 | N14: #SS1 > ELETROCENTRO | O14: BK-SP08-02000-DI-70-00001 BK-SP08-02000-MC-75-00002 BK-SP08-02000-DP-71-00002 | Q14: PAINEL DE MÉDIA TENSÃO 13,8kV
C15: MVS-2001 | F15: PRETA | G15: ISOLAÇÃO EPR 8,7/15 kV 105°C | I15: - | L15: 175 / 175 / 175
A16: MVS2001-EB2001-01F | C16: MVS-2001 | E16: 3x1/C#185 mm² | F16: =58 -> 58 | G16: NOTA 1 | I16: NA | K16: BOBINA 12 / BOBINA 13 / BOBINA 14 | L16: 58 / 58 / 58 | N16: ELETROCENTRO > CALDEIRA | O16: BK-SP08-02000-DI-70-00001 BK-SP08-02000-MC-75-00002 BK-SP08-02000-DP-71-00003 | Q16: CALDEIRA ELÉTRICA
C17: EB101 / 22.GV001 / EB2001 | F17: PRETA | G17: ISOLAÇÃO EPR 8,7/15 kV 105°C | I17: - | L17: 58 / 58 / 58
A18: CABOS DE BAIXA TENSÃO - 24Vcc
A19: QDI2103-RCK2001-01F | C19: QDI-21.03 | E19: 1x3/C#4 mm² | F19: 11 | G19: NOTA 1 | I19: NA | K19: BOBINA 15 | L19: 11 | N19: SALA DE CONTROLE | O19: BK-SP08-02100-DI-74-00002 BK-SP08-02000-MC-74-00001 | Q19: PAINEL DE INTERFACE - MODBUS TCP IP
C20: 61.PN005-BRK / RCK-20-01 | F20: PRETA | G20: ISOLAÇÃO EPR 0,6/1kV 90°C | I20: - | L20: =F19 -> 11
A21: CABOS DE BAIXA TENSÃO - 220V (COMANDO)
A22: LSB2001-01C | C22: LSB-2001 | E22: 1x2/C#2,5 mm² | F22: 22 | G22: NOTA 1 | I22: NA | K22: BOBINA 16 | L22: =F22 -> 22 | N22: ELETROCENTRO > FOTOCÉLULA | O22: BK-SP08-02000-DI-70-00001 BK-SP08-02000-MC-74-00001 BK-SP08-02000-DP-71-00001 | Q22: ACIONAMENTO ILUMINAÇÃO (FOTOCÉLULA)
C23: FOTOCÉLULA | F23: PRETA | G23: ISOLAÇÃO EPR 0,6/1kV 90°C | I23: - | L23: =F22 -> 22
A24: Notas:
A25: 1. Fabricante cadastrado no vendor list da BRASKEM;
A26: 2. Para mais informações sobre o encaminhamento dos cabos, consultar os documentos de referência;
A27: 3. Para a determinação do peso das bobinas, foram utilizados como referência os cabos dos modelos Afumex Flex 0,6 / 1kV e Compact 105 8,7 / 15kV, ambos do fabricante Prysmian;
A28: As Bobinas foram dimensionadas de forma a não exceder o peso máximo de 200Kg solicitado pelo cliente, exceto quando necessário. Destaca-se que deverão ser observados os comprimentos padrão de fabricação das bobinas adotados pelo fornecedor no momento de aquisição. Os valores deverão ser iguais ou superiores às quantidades especificadas.
A29: Bobina 1 - 686m - 143Kg - 1x3/C#4 mm² / Bobina 2 - 707m - 147Kg - 1x3/C#4 mm² / Bobina 3 - 578m - 146Kg - 1x4/C#4 mm² / Bobina 4 - 555m - 140Kg - 1x4/C#4 mm²;
A30: Bobina 5 - 84m - 29Kg - 1x4/C#6 mm² / Bobina 6 - 146m - 78,5Kg - 1x4/C#10 mm² / Bobina 7 - 210m - 279Kg - 1x4/C#25 mm² / Bobina 8 - 80m - 130Kg - 1x4/C#35 mm²;
A31: Bobina 9 - 175m - 379Kg - 1x1/C#185 mm² / Bobina 10 - 175m - 379Kg - 1x1/C#185 mm² / Bobina 11 - 175m - 379Kg - 1x1/C#185 mm² / Bobina 12 - 58m - 125,5Kg - 1x1/C#185 mm²;
A32: Bobina 13 - 58m - 125,5Kg - 1x1/C#185 mm² / Bobina 14 - 58m - 125,5Kg - 1x1/C#185 mm² / Bobina 15 - 11m - 2,5Kg - 1x3/C#4 mm² / Bobina 16 - 22m - 3Kg - 1x2/C#2,5 mm².
A34: Documentos de referência:
A35: 1. BK-SP08-02000-MC-74-00001 - MEMÓRIA DE CÁLCULO – CABOS – BAIXA TENSÃO;
A36: 2. BK-SP08-02000-DI-70-00001 - DIAGRAMA UNIFILAR GERAL;
... A42: 8. BK-SP08-02100-DI-74-00002 - QUADRO DE ALIMENTAÇÃO DE INSTRUMENTOS QDI-21.03.

Sheet APOIO
I1: CATALOGOS PRYSMIAN | J1: KG/KM | L1: BOBINA IDEAL 200KG
I2: 1x3/C#4 mm² | J2: 208
I3: 1x4/C#4 mm² | J3: 252
I4: 1x4/C#6 mm² | J4: 349
I5: 1x4/C#10 mm² | J5: 538
I6: 1x4/C#25 mm² | J6: 1327
I7: 1x4/C#35 mm² | J7: 1622
I8: 1x1/C#185 mm² | J8: 2164
I9: 1x2/C#2,5 mm² | J9: 131
I12: COMPRIMENTO DE CABO [M] | K12: PESO [KG]
I13: =SUMIF($G$53:$G$102,J13,$F$53:$F$102) -> 686 | J13: B1 | K13: =I13*J2/1000 -> 142.688 | L13: =I2 -> 1x3/C#4 mm²
I14: =SUMIF($G$53:$G$102,J14,$F$53:$F$102) -> 707 | J14: B2 | K14: =I14*J2/1000 -> 147.056 | L14: =I2 -> 1x3/C#4 mm²
I15: =SUMIF($G$53:$G$102,J15,$F$53:$F$102) -> 578 | J15: B3 | K15: =I15*J3/1000 -> 145.656 | L15: =I3 -> 1x4/C#4 mm²
I16: =SUMIF($G$53:$G$102,J16,$F$53:$F$102) -> 555 | J16: B4 | K16: =I16*J3/1000 -> 139.86 | L16: =I3 -> 1x4/C#4 mm²
I17: =SUMIF($G$53:$G$102,J17,$F$53:$F$102) -> 84 | J17: B5 | K17: =I17*J4/1000 -> 29.316 | L17: =I4 -> 1x4/C#6 mm²
I18: =SUMIF($G$53:$G$102,J18,$F$53:$F$102) -> 146 | J18: B6 | K18: =I18*J5/1000 -> 78.548 | L18: =I5 -> 1x4/C#10 mm²
I19: =SUMIF($G$53:$G$102,J19,$F$53:$F$102) -> 210 | J19: B7 | K19: =I19*J6/1000 -> 278.67 | L19: =I6 -> 1x4/C#25 mm²
I20: =SUMIF($G$53:$G$102,J20,$F$53:$F$102) -> 80 | J20: B8 | K20: =I20*J7/1000 -> 129.76 | L20: =I7 -> 1x4/C#35 mm²
I21: =F99 -> 175 | J21: B9 | K21: =I21*J8/1000 -> 378.7 | L21: =I8 -> 1x1/C#185 mm²
I22: =F99 -> 175 | J22: B10 | K22: =I22*J8/1000 -> 378.7 | L22: =I8 -> 1x1/C#185 mm²
I23: =F99 -> 175 | J23: B11 | K23: =I23*J8/1000 -> 378.7 | L23: =I8 -> 1x1/C#185 mm²
I24: =F100 -> 58 | J24: B12 | K24: =I24*J8/1000 -> 125.512 | L24: =I8 -> 1x1/C#185 mm²
I25: =F100 -> 58 | J25: B13 | K25: =I25*J8/1000 -> 125.512 | L25: =I8 -> 1x1/C#185 mm²
I26: =F100 -> 58 | J26: B14 | K26: =I26*J8/1000 -> 125.512 | L26: =I8 -> 1x1/C#185 mm²
I27: =SUMIF($G$53:$G$102,J27,$F$53:$F$102) -> 11 | J27: B15 | K27: =I27*J2/1000 -> 2.288 | L27: =I2 -> 1x3/C#4 mm²
I28: =SUMIF($G$53:$G$102,J28,$F$53:$F$102) -> 22 | J28: B16 | K28: =I28*J9/1000 -> 2.882 | L28: 1x2/C#2,5 mm²
C52: NÚMERO | D52: TAG | E52: FORMAÇÃO | F52: m | G52: BOBINA
C53: circuito 1 | D53: LSB-2001-MP2011-01F | E53: 1x3/C#4 mm² | F53: 66 | G53: B1
C54: circuito 2 | D54: LSB-2001-MP2012-01F | E54: 1x3/C#4 mm² | F54: 66 | G54: B1
C55: circuito 3 | D55: LSB-2001-MP2013-01F | E55: 1x3/C#4 mm² | F55: 66 | G55: B1
C56: circuito 4 | D56: LSB-2001-MP2015-01F | E56: 1x3/C#4 mm² | F56: 60 | G56: B1
C57: circuito 5 | D57: LSB-2001-MP2016-01F | E57: 1x3/C#4 mm² | F57: 60 | G57: B1
C58: circuito 6 | D58: LSB-2001-MP2019-01F | E58: 1x3/C#4 mm² | F58: 58 | G58: B1
C59: circuito 7 | D59: LSB-2001-MP2020-01F | E59: 1x3/C#4 mm² | F59: 58 | G59: B1
C60: circuito 8 | D60: LSB-2001-MP2021-01F | E60: 1x3/C#4 mm² | F60: 58 | G60: B1
C61: circuito 9 | D61: LSB-2001-MP2022-01F | E61: 1x3/C#4 mm² | F61: 58 | G61: B1
C62: circuito 10 | D62: LSB-2001-01L | E62: 1x3/C#4 mm² | F62: 95 | G62: B2
C63: circuito 11 | D63: LSB-2001-02L | E63: 1x3/C#4 mm² | F63: 95 | G63: B2
C64: circuito 12 | D64: LSB-2001-03L | E64: 1x3/C#4 mm² | F64: 84 | G64: B2
... C98: circuito 46 | D98: CCM-2001-C2003-01F | E98: 1x4/C#4 mm² | F98: 53 | G98: B4
...

Sheet LISTAS
A2: CENTRO LOGÍSTICO | E2: LOCAL DE ENTREGA DATABOOK
B3: CENTRO | C3: EQUIPO | D3: INSPEÇÃO | E3: Centro Logístico | F3: Endereço entrega Databook | G3: Contato | H3: e-mail | I3: Fones | J3: Projetista | K3: Disciplina | L3: OPCAO
A4: 01 | B4: SELECIONE CENTRO LOGÍSTICO | E4: BRASKEM S.A. UNIB-BA | F4: Rua Eteno, 1561, COPEC, Camaçari – BA, CEP - 42810-000 | G4: Lúcia Portela | H4: lucia.portela@braskem.com.br | I4: 55 (71) 3413-2169 | J4: JPNOR | K4: SELECIONE A DISCIPLINA | L4: -
A5: 02 | B5: AL01 - SALGEMA-AL | C5: Novo | D5: L | J5: GENPRO | K5: AUTOMAÇÃO | L5: X
A6: 03 | B6: AL02 - CS-AL | C6: Substituição | D6: A | J6: MANA | K6: CALDEIRARIA
A7: 04 | B7: AL03 - PVC-AL | C7: Recuperação | D7: B | J7: IDOM | K7: ELÉTRICA
A8: 05 | B8: AL04 - CINAL | D8: C | J8: PROGEN | K8: INSTRUMENTAÇÃO
A9: 06 | B9: AL05 - ALCLOR | D9: D | J9: KTY | K9: ROTATIVOS
A10: 07 | B10: BA01 - UNIB-BA | D10: NA | J10: LINDE | K10: TUBULAÇÃO
A11: 08 | B11: BA02 - CS-BA | E11: BRASKEM S.A. CS-AL | F11: Av. Assis Chateaubriand, 5260, Portal da Barra, Maceió – AL, CEP - 57010-900 | G11: Raquel Adornato | H11: raquel.adornato@braskem.com.br | I11: 55 (82) 3177-5188 | J11: CHEMTECH
A12: 09 | B12: BA03 - PVC-BA | E12: BRASKEM S.A. PVC-SP | F12: Rua Guamiranga, 1674, Vila Prudente, São Paulo - SP, CEP - 04220-000 | G12: Priscila Fernandes | H12: priscila.fernandes@braskem.com.br | I12: 55 (11) 3202-6534 | J12: PROCAD
A13: 10 | B13: BA04 - PE2-BA | E13: BRASKEM S.A. PP-RS | F13: Via Oeste, Lote 5, Passo Raso, Triunfo – RS, CEP - 95853-000 | G13: Aline Renz | H13: aline.renz@braskem.com.br | I13: 55 (51) 3721-8113 | J13: JPPA
A14: 11 | B14: BA05 - CPL-BA | J14: LUMMUS
A15: 12 | B15: BA06 - TERMINAL DE GASES-TEGAL | E15: BRASKEM S.A. PP3-SP | F15: Rodovia SP 332, km 134, Sitio Planalto Paulista, Paulinia - SP, CEP - 13140-000 | G15: Andrea Brasil | H15: andrea.brasil@gruparc.com.br | I15: 55 (11) 3957-7125 | J15: TECHNIP
A16: 13 | B16: BA07 - PE1-BA | J16: WORLEY PARSONS
A17: 14 | B17: BA08 - PET-BA | J17: STONE WEBSTER
B18: BA09 - ESCRITÓRIO SALVADOR | J18: FOSTER WHEELER
B19: BA10 - BRASKEM DISTRIB.-CAMAÇARI
B20: BA11 - PE3-BA
B21: BA12 - BRK-IMP
B22: BA13 - ETENODUTO
B23: BA14 - BRASPAR
B24: MA01 - TERMINAL ITAQUI | F24: PADRÃO DE PINTURA
B25: MG01 - CD-CONTAGEM
B26: PE01 - TERMINAL SUAPE | F26: Grau de Peparo da Superficie
B27: PE02 - ESCRITÓRIO RECIFE | G27: SELECIONE
B28: PR01 - CD-ARAUCÁRIA | G28: PS1 | H28: Preparo por limpeza mecânica - Grau ST3
B29: RJ01 - TERIO | G29: PS2 | H29: Preparo com jato abrasivo seco - Grau SA 2.1/2
B30: RJ02 - ESCRITÓRIO RIO | G30: PS3 | H30: Preparo com hidrojateamento - Grau WJ-1
B31: RS01 - PE-RS | G31: PS4 | H31: Preparo com hidrojateamento - Grau WJ-4
B32: RS02 - PP-RS | G32: N/A
B33: SC01 - TERMINAL IMBITUBA | F33: Tintas de Fundo
B34: SC02 - ESCRITÓRIO-FLORIANOPOLIS | G34: SELECIONE
B35: SC03 - BRASKEM DISTRIB.-JOINVILE | G35: RU | H35: Revestimento Único (TF+Acab. Fenólico)
B36: SP01 - PVC-SP | G36: TF1 | H36: Fosfato de zinco epoxi de alta espessura
B37: SP02 - ESCRITÓRIO VILLA LOBOS | G37: TF2 | H37: Etil silicato de zinco
B38: SP03 - TERMINAL SANTOS | G38: TF3 | H38: Epoxi isocianato (Tinta de aderência)
B39: SP04 - BRASKEM DISTRIB.-PAULINIA | G39: TF4 | H39: Epoxi pigmentada com alumínio
B40: SP05 - ESCRITÓRIO DUNAS | G40: TF5 | H40: Epoxi para superfícies úmidas
B41: SP08 - PP3-PAULINIA | G41: TF6 | H41: Tinta de fundo zinco epoxi
...
