Workbook

Sheet RESUMO
E3: RESUMO COMERCIAL
M5: OBRA
M6: ENG
H7: MARGEM REAL | J7: =G134 -> 0.12617233 | K7: VENDAS BRUTAS ULTIMOS 12 MESES | M7: 15000000
B8: ISENÇÃO PIS / COFINS | D8: NÃO | E8: COMISSÃO VENDEDOR EXTERNO | G8: 0 | H8: LUCRO MATERIAIS | J8: 0.1 | K8: PRAZO TOTAL (MESES) | M8: 2
B9: CONSUMIDOR FINAL | D9: SIM | E9: COMISSÃO REPRESENTANTE | G9: 0 | H9: LUCRO SERVIÇOS | J9: 0.1 | K9: ALÍQUOTA SIMPLES NACIONAL | M9: 0.12
B10: CONTRIBUINTE ICMS | D10: CONTRIBUINTE | E10: SERVIÇOS ENGENHARIA | G10: LUCRO REAL | H10: SERVIÇOS CAMPO | J10: LUCRO REAL | K10: MATERIAL | M10: LUCRO REAL
B11: ESTADO DESTINO | D11: SP
B13: SERVIÇOS DE ENGENHARIA | E13: Custo | F13: Venda Liq | G13: ENG | H13: DESPESAS DE ENGENHARIA | K13: Custo | L13: Venda Liq | M13: ENG
E14: =ServInt[[#Totals],[TOTAL]]+ServExt[[#Totals],[TOTAL]] -> 97488 | F14: =ServInt[[#Totals],[TOTAL3]]+ServExt[[#Totals],[TOTAL3]] -> 145539.29 | K14: ='SERVICOS AUTPRO'!L8+'SERVICOS AUTPRO'!L12+'SERVICOS AUTPRO'!L20 -> 44884 | L14: ='SERVICOS AUTPRO'!F8+'SERVICOS AUTPRO'!F12+'SERVICOS AUTPRO'!H20 -> 74620.834
B15: Impostos | C15: (+) Pis | E15: =IF($D$8="SIM",0%,IF($G$10=BASE!$Z$2,BASE!AB3,IF($G$10=BASE!$AC$2,BASE!AE3,IF($G$10=BASE!$AF$2,BASE!AH3,IF($G$10=BASE!$AI$2,BASE!AK3,BASE!AN3))))) -> 0.0165 | F15: =($F$21*E15) -> 2705.8009 | H15: Impostos | I15: (+) Pis | K15: =IF($D$8="SIM",0%,IF($G$10=BASE!$Z$2,BASE!AB3,IF($G$10=BASE!$AC$2,BASE!AE3,IF($G$10=BASE!$AF$2,BASE!AH3,IF($G$10=BASE!$AI$2,BASE!AK3,BASE!AN3))))) -> 0.0165 | L15: =($L$21*K15) -> 1435.8528
C16: (+) Cofins | E16: =IF($D$8="SIM",0%,IF($G$10=BASE!$Z$2,BASE!AB4,IF($G$10=BASE!$AC$2,BASE!AE4,IF($G$10=BASE!$AF$2,BASE!AH4,IF($G$10=BASE!$AI$2,BASE!AK4,BASE!AN4))))) -> 0.076 | F16: =($F$21*E16) -> 12463.083 | I16: (+) Cofins | K16: =IF($D$8="SIM",0%,IF($G$10=BASE!$Z$2,BASE!AB4,IF($G$10=BASE!$AC$2,BASE!AE4,IF($G$10=BASE!$AF$2,BASE!AH4,IF($G$10=BASE!$AI$2,BASE!AK4,BASE!AN4))))) -> 0.076 | L16: =($L$21*K16) -> 6613.625
C17: (+) Simples Nacional | E17: =IF($G$10=BASE!$Z$2,BASE!AB5,IF($G$10=BASE!$AC$2,BASE!AE5,IF($G$10=BASE!$AF$2,BASE!AH5,IF($G$10=BASE!$AI$2,BASE!AK5,BASE!AN5)))) -> 0 | F17: =($F$21*E17) -> 0 | I17: (+) Simples Nacional | K17: =IF($G$10=BASE!$Z$2,BASE!AB5,IF($G$10=BASE!$AC$2,BASE!AE5,IF($G$10=BASE!$AF$2,BASE!AH5,IF($G$10=BASE!$AI$2,BASE!AK5,BASE!AN5)))) -> 0 | L17: =($L$21*K17) -> 0
C18: (+) Iss | E18: 0.02 | F18: =($F$21*E19) -> 0 | I18: (+) Iss | K18: 0.05 | L18: =($L$21*K18) -> 4351.069
F19: =($F$21*E20) -> 0 | L19: =($L$21*K19) -> 0
F20: =($F$21*E21) -> 0 | L20: =($L$21*K20) -> 0
B21: Sub-Total: | F21: =(F14/(100%-SUM(E15:E18))) -> 163987.93 | H21: Sub-Total: | L21: =(L14/(100%-SUM(K15:K18))) -> 87021.381
B22: Sub-Total: | F22: =F20+F21 -> 163987.93 | H22: Sub-Total: | L22: =L20+L21 -> 87021.381
B23: SERVIÇOS DE MONTAGEM | E23: Custo | F23: Venda Liq | G23: OBRA | H23: DESPESAS DE MONTAGEM | K23: Custo | L23: Venda Liq | M23: OBRA
E24: =ServInt10[[#Totals],[TOTAL]]+ServExt8[[#Totals],[TOTAL]] -> 269517.6 | F24: =ServInt10[[#Totals],[TOTAL3]]+ServExt8[[#Totals],[TOTAL3]] -> 338123.27 | K24: ='SERVICOS MONTAGEM'!L7+'SERVICOS MONTAGEM'!L11+'SERVICOS MONTAGEM'!L19 -> 229642 | L24: ='SERVICOS MONTAGEM'!F7+'SERVICOS MONTAGEM'!F11+'SERVICOS MONTAGEM'!H19 -> 288097.34
B25: Impostos | C25: (+) Pis | E25: =IF($D$8="SIM",0%,IF($J$10=BASE!$Z$2,BASE!AB3,IF($J$10=BASE!$AC$2,BASE!AE3,IF($J$10=BASE!$AF$2,BASE!AH3,IF($J$10=BASE!$AI$2,BASE!AK3,BASE!AN3))))) -> 0.0165 | F25: =($F$31*E25) -> 6286.2355 | H25: Impostos | I25: (+) Pis | K25: =IF($D$8="SIM",0%,IF($G$10=BASE!$Z$2,BASE!AB3,IF($G$10=BASE!$AC$2,BASE!AE3,IF($G$10=BASE!$AF$2,BASE!AH3,IF($G$10=BASE!$AI$2,BASE!AK3,BASE!AN3))))) -> 0.0165 | L25: =($L$31*K25) -> 5356.176
C26: (+) Cofins | E26: =IF($D$8="SIM",0%,IF($J$10=BASE!$Z$2,BASE!AB4,IF($J$10=BASE!$AC$2,BASE!AE4,IF($J$10=BASE!$AF$2,BASE!AH4,IF($J$10=BASE!$AI$2,BASE!AK4,BASE!AN4))))) -> 0.076 | F26: =($F$31*E26) -> 28954.782 | I26: (+) Cofins | K26: =IF($D$8="SIM",0%,IF($G$10=BASE!$Z$2,BASE!AB4,IF($G$10=BASE!$AC$2,BASE!AE4,IF($G$10=BASE!$AF$2,BASE!AH4,IF($G$10=BASE!$AI$2,BASE!AK4,BASE!AN4))))) -> 0.076 | L26: =($L$31*K26) -> 24670.871
C27: (+) Simples Nacional | E27: =IF($J$10=BASE!$Z$2,BASE!AB5,IF($J$10=BASE!$AC$2,BASE!AE5,IF($J$10=BASE!$AF$2,BASE!AH5,IF($J$10=BASE!$AI$2,BASE!AK5,BASE!AN5)))) -> 0 | F27: =($F$31*E27) -> 0 | I27: (+) Simples Nacional | K27: =IF($G$10=BASE!$Z$2,BASE!AB5,IF($G$10=BASE!$AC$2,BASE!AE5,IF($G$10=BASE!$AF$2,BASE!AH5,IF($G$10=BASE!$AI$2,BASE!AK5,BASE!AN5)))) -> 0 | L27: =($L$31*K27) -> 0
C28: (+) Iss | E28: 0.02 | F28: =($F$31*E28) -> 7619.6794 | I28: (+) Iss | K28: 0.02 | L28: =($L$31*K28) -> 6492.3345
F29: =($F$31*E29) -> 0 | I29: (+) IR CSLL | L29: =($L$31*K29) -> 0
B31: Sub-Total: | F31: =(F24/(100%-SUM(E25:E29))) -> 380983.97 | H31: Sub-Total: | L31: =(L24/(100%-SUM(K25:K29))) -> 324616.72
B32: Sub-Total: | F32: =F30+F31 -> 380983.97 | H32: Sub-Total: | L32: =L30+L31 -> 324616.72
B33: TERCEIROS E LOCAÇÕES | E33: Custo | F33: Venda Liq | G33: SELECIONAR
E34: =ServTerc[[#Totals],[TOTAL CUSTO]] -> 177860 | F34: =ServTerc[[#Totals],[TOTAL VENDA]] -> 195820.93 | G34: OBRA
B35: Impostos | C35: (+) Pis | E35: =IF($G$34=$G$13,E15,E25) -> 0.0165 | F35: =($F$41*E35) -> 3640.6144 | I35: DESCRIÇÃO | K35: CÓDIGO / NCM | L35: VALOR S/ IPI | M35: VALOR C/ IPI
C36: (+) Cofins | E36: =IF($G$34=$G$13,E16,E26) -> 0.076 | F36: =($F$41*E36) -> 16768.89 | I36: SERVIÇOS DE ENGENHARIA | K36: 07.01 | L36: =IF(G34="ENG",F42+F22+L22,F22+L22) -> 251009.31 | M36: =L36 -> 251009.31
C37: (+) Simples Nacional | E37: =IF($G$34=$G$13,E17,E27) -> 0 | F37: =($F$41*E37) -> 0 | I37: SERVIÇOS DE INSTALAÇÃO OU OBRAS | K37: 14.01 / 14.06 / 07.02 | L37: =IF(G34="ENG",F32+L32,+F32+L32+F42) -> 926243.99 | M37: =L37 -> 926243.99
C38: (+) Iss | E38: =IF($G$34=$G$13,E18,E28) -> 0.02 | F38: =($F$41*E38) -> 4412.8659 | I38: SISTEMA DE ENERGIA | K38: 8537.20.90 | L38: =F55 -> 259656.49 | M38: =F58 -> 259656.49
F39: =($F$41*E39) -> 0 | I39: PAINÉIS/SISTEMA DE AUTOMAÇÃO | K39: 8537.10.90 | L39: =F70 -> 9430.4315 | M39: =F73 -> 9430.4315
I40: SUB TOTAL | L40: =SUM(L36:L39) -> 1446340.2 | M40: =SUM(M36:M39) -> 1446340.2
B41: Sub-Total: | F41: =(F34/(100%-SUM(E35:E39))) -> 220643.3 | I41: FATURAMENTO DIRETO | L41: ='FAT. DIRETO'!K43 -> 397106.92
B42: Sub-Total: | F42: =F40+F41 -> 220643.3 | I42: CONDIÇÃO DE PAGAMENTO | L42: 28 dias
B44: MATERIAIS CAMPO | E44: Custo | F44: Venda Liq | G44: MATERIAL DE CAMPO | I44: SINAL > 20% | L44: SIM
E45: =MateriaisCampo[[#Totals],[TOTAL C/ IPI]] -> 210754.89 | F45: =MateriaisCampo[[#Totals],[VENDA]] -> 204479.49
B46: Impostos | C46: (+) ICMS | E46: =IF(OR($M$10="EXPORTAÇÃO",$M$10="SIMPLES RESENDE",$M$10="SIMPLES YAMA"),0%,IF($D$11="SP",BASE!$AQ$40,BASE!$AQ$40)) -> 0.12 | F46: =IF(D9="SIM",E46*F58,E46*F55) -> 31158.779 | I46: TOTAL GERAL | L46: =L40+L41 -> 1843447.1 | M46: =M40+L41 -> 1843447.1
...

Sheet SERVICOS AUTPRO
F2: ORÇAMENTO DETALHADO
D6: HOSPEDAGEM | H6: CUSTO | L6: CUSTO
D7: DESCRIÇÃO | E7: QUANTIDADE | F7: TOTAL | H7: VALOR HOTEL | O7: MARK-UP
D8: HOSPEDAGEM | E8: =ServExt[[#Totals],[TOTAL4]]/2 -> 140 | F8: =(E8*H8)/O8 -> 37620.939 | H8: 180 | L8: =(E8*H8) -> 25200 | O8: =BASE!$W$60 -> 0.66983974
D10: ALIMENTAÇÃO | H10: CUSTO | L10: CUSTO
D11: DESCRIÇÃO | E11: QUANTIDADE | F11: TOTAL | H11: VALOR REFEIÇÃO | O11: MARK-UP
D12: REFEIÇÕES | E12: =ServExt[[#Totals],[TOTAL4]] -> 280 | F12: =(E12*H12)/O12 -> 16720.417 | H12: 40 | L12: =(E12*H12) -> 11200 | O12: =BASE!$W$60 -> 0.66983974
D14: TRANSPORTE | J14: MESES | L14: CUSTO
D15: DESCRIÇÃO | E15: VIAGENS | F15: PEDÁGIOS | G15: KM | H15: TOTAL | O15: MARK-UP
D16: MOBILIZAÇÃO (POR TRANSLADO) | E16: 6 | F16: 75 | G16: 234 | H16: =(((G16*E16*BASE!M3)+(F16*E16))/O16) -> 2767.8262 | J16: 2 | L16: =((G16*E16*BASE!M3)+(F16*E16)) -> 1854 | O16: =BASE!$W$60 -> 0.66983974
D17: HOTEL PARA OBRA | E17: 120 | G17: 15 | H17: =(((G17*E17*BASE!M4)+(F17*E17))/O17) -> 2284.1284 | L17: =((G17*E17*BASE!M4)+(F17*E17)) -> 1530 | O17: =BASE!$W$60 -> 0.66983974
D18: ALUGUEL CARRO MENSAL | E18: Carros: | G18: =ROUNDUP(ServExt[[#Totals],[Coluna1]]/4,0) -> 2 | H18: =(L18/O18)*G18 -> 15227.523 | L18: =IF(ServExt[[#Totals],[DIAS]]>=30,BASE!W3*(J16),ServExt[[#Totals],[DIAS]]*BASE!W4*1.3) -> 5100 | O18: =BASE!$W$60 -> 0.66983974
D19: PASSAGEM AEREA | H19: =L19/O19 -> 0 | L19: =F19*E19 -> 0 | O19: =BASE!$W$60 -> 0.66983974
D20: TOTAL: | H20: =SUM(H16:I19) -> 20279.478 | L20: =SUM(L16:L19) -> 8484
B22: SERVIÇOS INTERNOS | W22: SERVIÇOS EXTERNOS | AR22: LEGENDA
B23: DESCRIÇÃO | E23: PROFISSIONAL | F23: Profissional | G23: REGIME DE TRABALHO | K23: CUSTO | T23: VENDA | W23: DESCRIÇÃO | Z23: PROFISSIONAL | AA23: Profissional | AB23: REGIME DE TRABALHO | AF23: CUSTO | AP23: VENDA | AR23: 1 | AS23: Especialista Eletricista I
B24: ITEM | C24: CENTRO DE CUSTO | D24: SERVIÇO | E24: CÓDIGO | F24: DESCRIÇÃO FUNÇÃO | G24: DIAS | H24: PESSOAS | I24: HORAS DIA | J24: TIPO H | K24: HE CALC | L24: TOTAL HORAS | M24: R$ / HORA | N24: TOTAL | O24: MARK-UP | P24: HORA | Q24: TOTAL3 | R24: TOTAL4 | S24: MULTA | T24: VENDA COM IMPOSTOS | W24: ITEM | X24: CENTRO DE CUSTO | Y24: SERVIÇO | Z24: CÓDIGO | AA24: DESCRIÇÃO FUNÇÃO | AB24: DIAS | AC24: PESSOAS | AD24: HORAS DIA | AE24: TIPO H | AF24: HE CALC | AG24: TOTAL HORAS | AH24: R$ / HORA | AI24: TOTAL | AJ24: MARK-UP | AK24: HORA | AL24: TOTAL3 | AM24: TOTAL4 | AN24: MULTA | AO24: Coluna1 | AP24: VENDA COM IMPOSTOS | AR24: 2 | AS24: Especialista Eletricista II
B25: 1 | C25: Projetos | D25: AS-BUILT DE PROJETOS E DOCUMENTAÇÕES | E25: 30 | F25: =LOOKUP('SERVICOS AUTPRO'!$E$25:$E$64,BASE!A$4:A$125,BASE!B$4:B$125) -> Projetista Elétrico V | G25: 40 | H25: 1 | I25: 9 | J25: NORMAL | K25: =_xlfn.IFS('SERVICOS AUTPRO'!$J$25:$J$64="EXTRA 150%",((1)*2.5),'SERVICOS AUTPRO'!$J$25:$J$64="EXTRA 100%",((1)*2),'SERVICOS AUTPRO'!$J$25:$J$64="EXTRA 75%",((1)*1.75),'SERVICOS AUTPRO'!$J$25:$J$64="EXTRA 50%",((1)*1.5),'SERVICOS AUTPRO'!$J$25:$J$64="NORMAL",((1))) -> 1 | L25: =ServInt[[#This Row],[DIAS]]*ServInt[[#This Row],[PESSOAS]]*ServInt[[#This Row],[HORAS DIA]] -> 360 | M25: =(IF(ServInt[[#This Row],[CÓDIGO]]="","",LOOKUP(E25,BASE!A$4:A$125,BASE!G$4:G$125)))*ServInt[[#This Row],[HE CALC]] -> 40.8 | N25: =ServInt[[#This Row],[TOTAL HORAS]]*ServInt[[#This Row],[R$ / HORA]] -> 14688 | O25: =BASE!$W$60 -> 0.66983974 | P25: =M25/O25 -> 60.910092 | Q25: =N25/O25 -> 21927.633 | S25: =(IF(E25="","",LOOKUP(E25,BASE!A$4:A$19,BASE!E$4:E$19)))*ServInt[[#This Row],[TOTAL HORAS]] -> 1100.8979 | T25: =IFERROR(ServInt[[#This Row],[TOTAL3]]*(RESUMO!$F$22/RESUMO!$F$14),0) -> 24707.192 | W25: 1 | X25: Sistemas | Y25: Serviço | Z25: 50 | AA25: =LOOKUP(Z25,BASE!A$4:A$125,BASE!B$4:B$125) -> Eletricista Força e Comando V | AB25: 20 | AC25: 1 | AD25: 10 | AE25: NORMAL | AF25: =_xlfn.IFS(ServExt[[#This Row],[TIPO H]]="EXTRA 150%",((1)*2.5),ServExt[[#This Row],[TIPO H]]="EXTRA 100%",((1)*2),ServExt[[#This Row],[TIPO H]]="EXTRA 75%",((1)*1.75),ServExt[[#This Row],[TIPO H]]="EXTRA 50%",((1)*1.5),ServExt[[#This Row],[TIPO H]]="NORMAL",((1))) -> 1 | AG25: =ServExt[[#This Row],[DIAS]]*ServExt[[#This Row],[PESSOAS]]*ServExt[[#This Row],[HORAS DIA]] -> 200 | AH25: =(IF(Z25="","",LOOKUP(Z25,BASE!A$4:A$125,BASE!H$4:H$125)))*ServExt[[#This Row],[HE CALC]] -> 39 | AI25: =ServExt[[#This Row],[TOTAL HORAS]]*ServExt[[#This Row],[R$ / HORA]] -> 7800 | AJ25: =BASE!$W$60 -> 0.66983974 | AK25: =AH25/AJ25 -> 58.222882 | AL25: =AI25/AJ25 -> 11644.576 | AM25: =IF(OR(ServExt[[#This Row],[TIPO H]]="NORMAL",ServExt[[#This Row],[HORAS DIA]]>=8),ServExt[[#This Row],[PESSOAS]]*ServExt[[#This Row],[DIAS]]*2,0) -> 40 | AN25: =(IF(Z25="","",LOOKUP(Z25,BASE!A$4:A$19,BASE!E$4:E$19)))*ServExt[[#This Row],[TOTAL HORAS]] -> 611.60995 | AO25: =IF(ServExt[[#This Row],[TIPO H]]="NORMAL",ServExt[[#This Row],[PESSOAS]],0) -> 1 | AP25: =IFERROR(ServExt[[#This Row],[TOTAL3]]*(RESUMO!$F$22/RESUMO!$F$14),0) -> 13120.649 | AR25: 3 | AS25: Especialista Eletricista III
B26: 2 | C26: Projetos | D26: Serviço | E26: 0 | F26: =LOOKUP('SERVICOS AUTPRO'!$E$25:$E$64,BASE!A$4:A$125,BASE!B$4:B$125) -> 0 | I26: 80 | J26: NORMAL | K26: =_xlfn.IFS('SERVICOS AUTPRO'!$J$25:$J$44="EXTRA 150%",((1)*2.5),'SERVICOS AUTPRO'!$J$25:$J$44="EXTRA 100%",((1)*2),'SERVICOS AUTPRO'!$J$25:$J$44="EXTRA 75%",((1)*1.75),'SERVICOS AUTPRO'!$J$25:$J$44="EXTRA 50%",((1)*1.5),'SERVICOS AUTPRO'!$J$25:$J$44="NORMAL",((1))) -> 1 | L26: =ServInt[[#This Row],[DIAS]]*ServInt[[#This Row],[PESSOAS]]*ServInt[[#This Row],[HORAS DIA]] -> 0 | M26: =(IF(ServInt[[#This Row],[CÓDIGO]]="","",LOOKUP(E26,BASE!A$4:A$125,BASE!G$4:G$125)))*ServInt[[#This Row],[HE CALC]] -> 0 | N26: =ServInt[[#This Row],[TOTAL HORAS]]*ServInt[[#This Row],[R$ / HORA]] -> 0 | O26: =BASE!$W$60 -> 0.66983974 | P26: =M26/O26 -> 0 | Q26: =N26/O26 -> 0 | S26: =(IF(E26="","",LOOKUP(E26,BASE!A$4:A$19,BASE!E$4:E$19)))*ServInt[[#This Row],[TOTAL HORAS]] -> 0 | T26: =IFERROR(ServInt[[#This Row],[TOTAL3]]*(RESUMO!$F$22/RESUMO!$F$14),0) -> 0 | W26: 2 | X26: Sistemas | Y26: Serviço | Z26: 5 | AA26: =LOOKUP(Z26,BASE!A$4:A$125,BASE!B$4:B$125) -> Especialista Eletricista V | AB26: 45 | AC26: 1 | AD26: 10 | AE26: NORMAL | AF26: =_xlfn.IFS(ServExt[[#This Row],[TIPO H]]="EXTRA 150%",((1)*2.5),ServExt[[#This Row],[TIPO H]]="EXTRA 100%",((1)*2),ServExt[[#This Row],[TIPO H]]="EXTRA 75%",((1)*1.75),ServExt[[#This Row],[TIPO H]]="EXTRA 50%",((1)*1.5),ServExt[[#This Row],[TIPO H]]="NORMAL",((1))) -> 1 | AG26: =ServExt[[#This Row],[DIAS]]*ServExt[[#This Row],[PESSOAS]]*ServExt[[#This Row],[HORAS DIA]] -> 450 | AH26: =(IF(Z26="","",LOOKUP(Z26,BASE!A$4:A$125,BASE!H$4:H$125)))*ServExt[[#This Row],[HE CALC]] -> 84 | AI26: =ServExt[[#This Row],[TOTAL HORAS]]*ServExt[[#This Row],[R$ / HORA]] -> 37800 | AJ26: =BASE!$W$60 -> 0.66983974 | AK26: =AH26/AJ26 -> 125.40313 | AL26: =AI26/AJ26 -> 56431.409 | AM26: =IF(OR(ServExt[[#This Row],[TIPO H]]="NORMAL",ServExt[[#This Row],[HORAS DIA]]>=8),ServExt[[#This Row],[PESSOAS]]*ServExt[[#This Row],[DIAS]]*2,0) -> 90 | AN26: =(IF(Z26="","",LOOKUP(Z26,BASE!A$4:A$19,BASE!E$4:E$19)))*ServExt[[#This Row],[TOTAL HORAS]] -> 1376.1224 | AO26: =IF(ServExt[[#This Row],[TIPO H]]="NORMAL",ServExt[[#This Row],[PESSOAS]],0) -> 1 | AP26: =IFERROR(ServExt[[#This Row],[TOTAL3]]*(RESUMO!$F$22/RESUMO!$F$14),0) -> 63584.686 | AR26: 4 | AS26: Especialista Eletricista IV
B27: 3 | C27: Projetos | D27: Serviço | E27: 0 | F27: =LOOKUP('SERVICOS AUTPRO'!$E$25:$E$64,BASE!A$4:A$125,BASE!B$4:B$125) -> 0 | I27: 8.8 | J27: NORMAL | K27: =_xlfn.IFS('SERVICOS AUTPRO'!$J$25:$J$44="EXTRA 150%",((1)*2.5),'SERVICOS AUTPRO'!$J$25:$J$44="EXTRA 100%",((1)*2),'SERVICOS AUTPRO'!$J$25:$J$44="EXTRA 75%",((1)*1.75),'SERVICOS AUTPRO'!$J$25:$J$44="EXTRA 50%",((1)*1.5),'SERVICOS AUTPRO'!$J$25:$J$44="NORMAL",((1))) -> 1 | L27: =ServInt[[#This Row],[DIAS]]*ServInt[[#This Row],[PESSOAS]]*ServInt[[#This Row],[HORAS DIA]] -> 0 | M27: =(IF(ServInt[[#This Row],[CÓDIGO]]="","",LOOKUP(E27,BASE!A$4:A$125,BASE!G$4:G$125)))*ServInt[[#This Row],[HE CALC]] -> 0 | N27: =ServInt[[#This Row],[TOTAL HORAS]]*ServInt[[#This Row],[R$ / HORA]] -> 0 | O27: =BASE!$W$60 -> 0.66983974 | P27: =M27/O27 -> 0 | Q27: =N27/O27 -> 0 | S27: =(IF(E27="","",LOOKUP(E27,BASE!A$4:A$19,BASE!E$4:E$19)))*ServInt[[#This Row],[TOTAL HORAS]] -> 0 | T27: =IFERROR(ServInt[[#This Row],[TOTAL3]]*(RESUMO!$F$22/RESUMO!$F$14),0) -> 0 | W27: 3 | X27: Sistemas | Y27: Serviço | Z27: 65 | AA27: =LOOKUP(Z27,BASE!A$4:A$125,BASE!B$4:B$125) -> Instrumentista Tubista V | AB27: 45 | AC27: 1 | AD27: 10 | AE27: NORMAL | AF27: =_xlfn.IFS(ServExt[[#This Row],[TIPO H]]="EXTRA 150%",((1)*2.5),ServExt[[#This Row],[TIPO H]]="EXTRA 100%",((1)*2),ServExt[[#This Row],[TIPO H]]="EXTRA 75%",((1)*1.75),ServExt[[#This Row],[TIPO H]]="EXTRA 50%",((1)*1.5),ServExt[[#This Row],[TIPO H]]="NORMAL",((1))) -> 1 | AG27: =ServExt[[#This Row],[DIAS]]*ServExt[[#This Row],[PESSOAS]]*ServExt[[#This Row],[HORAS DIA]] -> 450 | AH27: =(IF(Z27="","",LOOKUP(Z27,BASE!A$4:A$125,BASE!H$4:H$125)))*ServExt[[#This Row],[HE CALC]] -> 42 | AI27: =ServExt[[#This Row],[TOTAL HORAS]]*ServExt[[#This Row],[R$ / HORA]] -> 18900 | AJ27: =BASE!$W$60 -> 0.66983974 | AK27: =AH27/AJ27 -> 62.701565 | AL27: =AI27/AJ27 -> 28215.704 | AM27: =IF(OR(ServExt[[#This Row],[TIPO H]]="NORMAL",ServExt[[#This Row],[HORAS DIA]]>=8),ServExt[[#This Row],[PESSOAS]]*ServExt[[#This Row],[DIAS]]*2,0) -> 90 | AN27: =(IF(Z27="","",LOOKUP(Z27,BASE!A$4:A$19,BASE!E$4:E$19)))*ServExt[[#This Row],[TOTAL HORAS]] -> 1376.1224 | AO27: =IF(ServExt[[#This Row],[TIPO H]]="NORMAL",ServExt[[#This Row],[PESSOAS]],0) -> 1 | AP27: =IFERROR(ServExt[[#This Row],[TOTAL3]]*(RESUMO!$F$22/RESUMO!$F$14),0) -> 31792.343 | AR27: 5 | AS27: Especialista Eletricista V
B28: 4 | C28: Projetos | D28: Serviço | E28: 0 | F28: =LOOKUP('SERVICOS AUTPRO'!$E$25:$E$64,BASE!A$4:A$125,BASE!B$4:B$125) -> 0 | I28: 8.8 | J28: NORMAL | K28: =_xlfn.IFS('SERVICOS AUTPRO'!$J$25:$J$44="EXTRA 150%",((1)*2.5),'SERVICOS AUTPRO'!$J$25:$J$44="EXTRA 100%",((1)*2),'SERVICOS AUTPRO'!$J$25:$J$44="EXTRA 75%",((1)*1.75),'SERVICOS AUTPRO'!$J$25:$J$44="EXTRA 50%",((1)*1.5),'SERVICOS AUTPRO'!$J$25:$J$44="NORMAL",((1))) -> 1 | L28: =ServInt[[#This Row],[DIAS]]*ServInt[[#This Row],[PESSOAS]]*ServInt[[#This Row],[HORAS DIA]] -> 0 | M28: =(IF(ServInt[[#This Row],[CÓDIGO]]="","",LOOKUP(E28,BASE!A$4:A$125,BASE!G$4:G$125)))*ServInt[[#This Row],[HE CALC]] -> 0 | N28: =ServInt[[#This Row],[TOTAL HORAS]]*ServInt[[#This Row],[R$ / HORA]] -> 0 | O28: =BASE!$W$60 -> 0.66983974 | P28: =M28/O28 -> 0 | Q28: =N28/O28 -> 0 | S28: =(IF(E28="","",LOOKUP(E28,BASE!A$4:A$19,BASE!E$4:E$19)))*ServInt[[#This Row],[TOTAL HORAS]] -> 0 | T28: =IFERROR(ServInt[[#This Row],[TOTAL3]]*(RESUMO!$F$22/RESUMO!$F$14),0) -> 0 | W28: 4 | X28: Sistemas | Y28: Serviço | Z28: 68 | AA28: =LOOKUP(Z28,BASE!A$4:A$125,BASE!B$4:B$125) -> Coodernador de Obras | AB28: 20 | AC28: 1 | AD28: 10 | AE28: NORMAL | AF28: =_xlfn.IFS(ServExt[[#This Row],[TIPO H]]="EXTRA 150%",((1)*2.5),ServExt[[#This Row],[TIPO H]]="EXTRA 100%",((1)*2),ServExt[[#This Row],[TIPO H]]="EXTRA 75%",((1)*1.75),ServExt[[#This Row],[TIPO H]]="EXTRA 50%",((1)*1.5),ServExt[[#This Row],[TIPO H]]="NORMAL",((1))) -> 1 | AG28: =ServExt[[#This Row],[DIAS]]*ServExt[[#This Row],[PESSOAS]]*ServExt[[#This Row],[HORAS DIA]] -> 200 | AH28: =(IF(Z28="","",LOOKUP(Z28,BASE!A$4:A$125,BASE!H$4:H$125)))*ServExt[[#This Row],[HE CALC]] -> 69 | AI28: =ServExt[[#This Row],[TOTAL HORAS]]*ServExt[[#This Row],[R$ / HORA]] -> 13800 | AJ28: =BASE!$W$60 -> 0.66983974 | AK28: =AH28/AJ28 -> 103.00971 | AL28: =AI28/AJ28 -> 20601.943 | AM28: =IF(OR(ServExt[[#This Row],[TIPO H]]="NORMAL",ServExt[[#This Row],[HORAS DIA]]>=8),ServExt[[#This Row],[PESSOAS]]*ServExt[[#This Row],[DIAS]]*2,0) -> 40 | AN28: =(IF(Z28="","",LOOKUP(Z28,BASE!A$4:A$19,BASE!E$4:E$19)))*ServExt[[#This Row],[TOTAL HORAS]] -> 611.60995 | AO28: =IF(ServExt[[#This Row],[TIPO H]]="NORMAL",ServExt[[#This Row],[PESSOAS]],0) -> 1 | AP28: =IFERROR(ServExt[[#This Row],[TOTAL3]]*(RESUMO!$F$22/RESUMO!$F$14),0) -> 23213.457 | AR28: 6 | AS28: Especialista Controle e Automação I
B29: 5 | C29: Projetos | D29: Serviço | E29: 0 | F29: =LOOKUP('SERVICOS AUTPRO'!$E$25:$E$64,BASE!A$4:A$125,BASE!B$4:B$125) -> 0 | I29: 8.8 | J29: NORMAL | K29: =_xlfn.IFS('SERVICOS AUTPRO'!$J$25:$J$44="EXTRA 150%",((1)*2.5),'SERVICOS AUTPRO'!$J$25:$J$44="EXTRA 100%",((1)*2),'SERVICOS AUTPRO'!$J$25:$J$44="EXTRA 75%",((1)*1.75),'SERVICOS AUTPRO'!$J$25:$J$44="EXTRA 50%",((1)*1.5),'SERVICOS AUTPRO'!$J$25:$J$44="NORMAL",((1))) -> 1 | L29: =ServInt[[#This Row],[DIAS]]*ServInt[[#This Row],[PESSOAS]]*ServInt[[#This Row],[HORAS DIA]] -> 0 | M29: =(IF(ServInt[[#This Row],[CÓDIGO]]="","",LOOKUP(E29,BASE!A$4:A$125,BASE!G$4:G$125)))*ServInt[[#This Row],[HE CALC]] -> 0 | N29: =ServInt[[#This Row],[TOTAL HORAS]]*ServInt[[#This Row],[R$ / HORA]] -> 0 | O29: =BASE!$W$60 -> 0.66983974 | P29: =M29/O29 -> 0 | Q29: =N29/O29 -> 0 | S29: =(IF(E29="","",LOOKUP(E29,BASE!A$4:A$19,BASE!E$4:E$19)))*ServInt[[#This Row],[TOTAL HORAS]] -> 0 | T29: =IFERROR(ServInt[[#This Row],[TOTAL3]]*(RESUMO!$F$22/RESUMO!$F$14),0) -> 0 | W29: 5 | X29: Sistemas | Y29: Serviço | Z29: 30 | AA29: =LOOKUP(Z29,BASE!A$4:A$125,BASE!B$4:B$125) -> Projetista Elétrico V | AB29: 10 | AC29: 1 | AD29: 10 | AE29: NORMAL | AF29: =_xlfn.IFS(ServExt[[#This Row],[TIPO H]]="EXTRA 150%",((1)*2.5),ServExt[[#This Row],[TIPO H]]="EXTRA 100%",((1)*2),ServExt[[#This Row],[TIPO H]]="EXTRA 75%",((1)*1.75),ServExt[[#This Row],[TIPO H]]="EXTRA 50%",((1)*1.5),ServExt[[#This Row],[TIPO H]]="NORMAL",((1))) -> 1 | AG29: =ServExt[[#This Row],[DIAS]]*ServExt[[#This Row],[PESSOAS]]*ServExt[[#This Row],[HORAS DIA]] -> 100 | AH29: =(IF(Z29="","",LOOKUP(Z29,BASE!A$4:A$125,BASE!H$4:H$125)))*ServExt[[#This Row],[HE CALC]] -> 45 | AI29: =ServExt[[#This Row],[TOTAL HORAS]]*ServExt[[#This Row],[R$ / HORA]] -> 4500 | AJ29: =BASE!$W$60 -> 0.66983974 | AK29: =AH29/AJ29 -> 67.180248 | AL29: =AI29/AJ29 -> 6718.0248 | AM29: =IF(OR(ServExt[[#This Row],[TIPO H]]="NORMAL",ServExt[[#This Row],[HORAS DIA]]>=8),ServExt[[#This Row],[PESSOAS]]*ServExt[[#This Row],[DIAS]]*2,0) -> 20 | AN29: =(IF(Z29="","",LOOKUP(Z29,BASE!A$4:A$19,BASE!E$4:E$19)))*ServExt[[#This Row],[TOTAL HORAS]] -> 305.80498 | AO29: =IF(ServExt[[#This Row],[TIPO H]]="NORMAL",ServExt[[#This Row],[PESSOAS]],0) -> 1 | AP29: =IFERROR(ServExt[[#This Row],[TOTAL3]]*(RESUMO!$F$22/RESUMO!$F$14),0) -> 7569.6055 | AR29: 7 | AS29: Especialista Controle e Automação Il
B30: 6 | C30: Projetos | D30: Serviço | E30: 0 | F30: =LOOKUP('SERVICOS AUTPRO'!$E$25:$E$64,BASE!A$4:A$125,BASE!B$4:B$125) -> 0 | I30: 8.8 | J30: NORMAL | K30: =_xlfn.IFS('SERVICOS AUTPRO'!$J$25:$J$44="EXTRA 150%",((1)*2.5),'SERVICOS AUTPRO'!$J$25:$J$44="EXTRA 100%",((1)*2),'SERVICOS AUTPRO'!$J$25:$J$44="EXTRA 75%",((1)*1.75),'SERVICOS AUTPRO'!$J$25:$J$44="EXTRA 50%",((1)*1.5),'SERVICOS AUTPRO'!$J$25:$J$44="NORMAL",((1))) -> 1 | L30: =ServInt[[#This Row],[DIAS]]*ServInt[[#This Row],[PESSOAS]]*ServInt[[#This Row],[HORAS DIA]] -> 0 | M30: =(IF(ServInt[[#This Row],[CÓDIGO]]="","",LOOKUP(E30,BASE!A$4:A$125,BASE!G$4:G$125)))*ServInt[[#This Row],[HE CALC]] -> 0 | N30: =ServInt[[#This Row],[TOTAL HORAS]]*ServInt[[#This Row],[R$ / HORA]] -> 0 | O30: =BASE!$W$60 -> 0.66983974 | P30: =M30/O30 -> 0 | Q30: =N30/O30 -> 0 | S30: =(IF(E30="","",LOOKUP(E30,BASE!A$4:A$19,BASE!E$4:E$19)))*ServInt[[#This Row],[TOTAL HORAS]] -> 0 | T30: =IFERROR(ServInt[[#This Row],[TOTAL3]]*(RESUMO!$F$22/RESUMO!$F$14),0) -> 0 | W30: 6 | X30: Sistemas | Y30: Serviço | Z30: 0 | AA30: =LOOKUP(Z30,BASE!A$4:A$125,BASE!B$4:B$125) -> 0 | AD30: 8.8 | AE30: NORMAL | AF30: =_xlfn.IFS(ServExt[[#This Row],[TIPO H]]="EXTRA 150%",((1)*2.5),ServExt[[#This Row],[TIPO H]]="EXTRA 100%",((1)*2),ServExt[[#This Row],[TIPO H]]="EXTRA 75%",((1)*1.75),ServExt[[#This Row],[TIPO H]]="EXTRA 50%",((1)*1.5),ServExt[[#This Row],[TIPO H]]="NORMAL",((1))) -> 1 | AG30: =ServExt[[#This Row],[DIAS]]*ServExt[[#This Row],[PESSOAS]]*ServExt[[#This Row],[HORAS DIA]] -> 0 | AH30: =(IF(Z30="","",LOOKUP(Z30,BASE!A$4:A$125,BASE!H$4:H$125)))*ServExt[[#This Row],[HE CALC]] -> 0 | AI30: =ServExt[[#This Row],[TOTAL HORAS]]*ServExt[[#This Row],[R$ / HORA]] -> 0 | AJ30: =BASE!$W$60 -> 0.66983974 | AK30: =AH30/AJ30 -> 0 | AL30: =AI30/AJ30 -> 0 | AM30: =IF(OR(ServExt[[#This Row],[TIPO H]]="NORMAL",ServExt[[#This Row],[HORAS DIA]]>=8),ServExt[[#This Row],[PESSOAS]]*ServExt[[#This Row],[DIAS]]*2,0) -> 0 | AN30: =(IF(Z30="","",LOOKUP(Z30,BASE!A$4:A$19,BASE!E$4:E$19)))*ServExt[[#This Row],[TOTAL HORAS]] -> 0 | AO30: =IF(ServExt[[#This Row],[TIPO H]]="NORMAL",ServExt[[#This Row],[PESSOAS]],0) -> 0 | AP30: =IFERROR(ServExt[[#This Row],[TOTAL3]]*(RESUMO!$F$22/RESUMO!$F$14),0) -> 0 | AR30: 8 | AS30: Especialista Controle e Automação III
B31: 7 | C31: Projetos | D31: Serviço | E31: 0 | F31: =LOOKUP('SERVICOS AUTPRO'!$E$25:$E$64,BASE!A$4:A$125,BASE!B$4:B$125) -> 0 | I31: 8.8 | J31: NORMAL | K31: =_xlfn.IFS('SERVICOS AUTPRO'!$J$25:$J$44="EXTRA 150%",((1)*2.5),'SERVICOS AUTPRO'!$J$25:$J$44="EXTRA 100%",((1)*2),'SERVICOS AUTPRO'!$J$25:$J$44="EXTRA 75%",((1)*1.75),'SERVICOS AUTPRO'!$J$25:$J$44="EXTRA 50%",((1)*1.5),'SERVICOS AUTPRO'!$J$25:$J$44="NORMAL",((1))) -> 1 | L31: =ServInt[[#This Row],[DIAS]]*ServInt[[#This Row],[PESSOAS]]*ServInt[[#This Row],[HORAS DIA]] -> 0 | M31: =(IF(ServInt[[#This Row],[CÓDIGO]]="","",LOOKUP(E31,BASE!A$4:A$125,BASE!G$4:G$125)))*ServInt[[#This Row],[HE CALC]] -> 0 | N31: =ServInt[[#This Row],[TOTAL HORAS]]*ServInt[[#This Row],[R$ / HORA]] -> 0 | O31: =BASE!$W$60 -> 0.66983974 | P31: =M31/O31 -> 0 | Q31: =N31/O31 -> 0 | S31: =(IF(E31="","",LOOKUP(E31,BASE!A$4:A$19,BASE!E$4:E$19)))*ServInt[[#This Row],[TOTAL HORAS]] -> 0 | T31: =IFERROR(ServInt[[#This Row],[TOTAL3]]*(RESUMO!$F$22/RESUMO!$F$14),0) -> 0 | W31: 7 | X31: Sistemas | Y31: Serviço | Z31: 0 | AA31: =LOOKUP(Z31,BASE!A$4:A$125,BASE!B$4:B$125) -> 0 | AD31: 8.8 | AE31: NORMAL | AF31: =_xlfn.IFS(ServExt[[#This Row],[TIPO H]]="EXTRA 150%",((1)*2.5),ServExt[[#This Row],[TIPO H]]="EXTRA 100%",((1)*2),ServExt[[#This Row],[TIPO H]]="EXTRA 75%",((1)*1.75),ServExt[[#This Row],[TIPO H]]="EXTRA 50%",((1)*1.5),ServExt[[#This Row],[TIPO H]]="NORMAL",((1))) -> 1 | AG31: =ServExt[[#This Row],[DIAS]]*ServExt[[#This Row],[PESSOAS]]*ServExt[[#This Row],[HORAS DIA]] -> 0 | AH31: =(IF(Z31="","",LOOKUP(Z31,BASE!A$4:A$125,BASE!H$4:H$125)))*ServExt[[#This Row],[HE CALC]] -> 0 | AI31: =ServExt[[#This Row],[TOTAL HORAS]]*ServExt[[#This Row],[R$ / HORA]] -> 0 | AJ31: =BASE!$W$60 -> 0.66983974 | AK31: =AH31/AJ31 -> 0 | AL31: =AI31/AJ31 -> 0 | AM31: =IF(OR(ServExt[[#This Row],[TIPO H]]="NORMAL",ServExt[[#This Row],[HORAS DIA]]>=8),ServExt[[#This Row],[PESSOAS]]*ServExt[[#This Row],[DIAS]]*2,0) -> 0 | AN31: =(IF(Z31="","",LOOKUP(Z31,BASE!A$4:A$19,BASE!E$4:E$19)))*ServExt[[#This Row],[TOTAL HORAS]] -> 0 | AO31: =IF(ServExt[[#This Row],[TIPO H]]="NORMAL",ServExt[[#This Row],[PESSOAS]],0) -> 0 | AP31: =IFERROR(ServExt[[#This Row],[TOTAL3]]*(RESUMO!$F$22/RESUMO!$F$14),0) -> 0 | AR31: 9 | AS31: Especialista Controle e Automação IV
B32: 8 | C32: Projetos | D32: Serviço | E32: 0 | F32: =LOOKUP('SERVICOS AUTPRO'!$E$25:$E$64,BASE!A$4:A$125,BASE!B$4:B$125) -> 0 | G32: 0 | I32: 8.8 | J32: NORMAL | K32: =_xlfn.IFS('SERVICOS AUTPRO'!$J$25:$J$44="EXTRA 150%",((1)*2.5),'SERVICOS AUTPRO'!$J$25:$J$44="EXTRA 100%",((1)*2),'SERVICOS AUTPRO'!$J$25:$J$44="EXTRA 75%",((1)*1.75),'SERVICOS AUTPRO'!$J$25:$J$44="EXTRA 50%",((1)*1.5),'SERVICOS AUTPRO'!$J$25:$J$44="NORMAL",((1))) -> 1 | L32: =ServInt[[#This Row],[DIAS]]*ServInt[[#This Row],[PESSOAS]]*ServInt[[#This Row],[HORAS DIA]] -> 0 | M32: =(IF(ServInt[[#This Row],[CÓDIGO]]="","",LOOKUP(E32,BASE!A$4:A$125,BASE!G$4:G$125)))*ServInt[[#This Row],[HE CALC]] -> 0 | N32: =ServInt[[#This Row],[TOTAL HORAS]]*ServInt[[#This Row],[R$ / HORA]] -> 0 | O32: =BASE!$W$60 -> 0.66983974 | P32: =M32/O32 -> 0 | Q32: =N32/O32 -> 0 | S32: =(IF(E32="","",LOOKUP(E32,BASE!A$4:A$19,BASE!E$4:E$19)))*ServInt[[#This Row],[TOTAL HORAS]] -> 0 | T32: =IFERROR(ServInt[[#This Row],[TOTAL3]]*(RESUMO!$F$22/RESUMO!$F$14),0) -> 0 | W32: 8 | X32: Sistemas | Y32: Serviço | Z32: 0 | AA32: =LOOKUP(Z32,BASE!A$4:A$125,BASE!B$4:B$125) -> 0 | AD32: 8.8 | AE32: NORMAL | AF32: =_xlfn.IFS(ServExt[[#This Row],[TIPO H]]="EXTRA 150%",((1)*2.5),ServExt[[#This Row],[TIPO H]]="EXTRA 100%",((1)*2),ServExt[[#This Row],[TIPO H]]="EXTRA 75%",((1)*1.75),ServExt[[#This Row],[TIPO H]]="EXTRA 50%",((1)*1.5),ServExt[[#This Row],[TIPO H]]="NORMAL",((1))) -> 1 | AG32: =ServExt[[#This Row],[DIAS]]*ServExt[[#This Row],[PESSOAS]]*ServExt[[#This Row],[HORAS DIA]] -> 0 | AH32: =(IF(Z32="","",LOOKUP(Z32,BASE!A$4:A$125,BASE!H$4:H$125)))*ServExt[[#This Row],[HE CALC]] -> 0 | AI32: =ServExt[[#This Row],[TOTAL HORAS]]*ServExt[[#This Row],[R$ / HORA]] -> 0 | AJ32: =BASE!$W$60 -> 0.66983974 | AK32: =AH32/AJ32 -> 0 | AL32: =AI32/AJ32 -> 0 | AM32: =IF(OR(ServExt[[#This Row],[TIPO H]]="NORMAL",ServExt[[#This Row],[HORAS DIA]]>=8),ServExt[[#This Row],[PESSOAS]]*ServExt[[#This Row],[DIAS]]*2,0) -> 0 | AN32: =(IF(Z32="","",LOOKUP(Z32,BASE!A$4:A$19,BASE!E$4:E$19)))*ServExt[[#This Row],[TOTAL HORAS]] -> 0 | AO32: =IF(ServExt[[#This Row],[TIPO H]]="NORMAL",ServExt[[#This Row],[PESSOAS]],0) -> 0 | AP32: =IFERROR(ServExt[[#This Row],[TOTAL3]]*(RESUMO!$F$22/RESUMO!$F$14),0) -> 0 | AR32: 10 | AS32: Especialista Controle e Automação V
B33: 9 | C33: Projetos | D33: Serviço | E33: 0 | F33: =LOOKUP('SERVICOS AUTPRO'!$E$25:$E$64,BASE!A$4:A$125,BASE!B$4:B$125) -> 0 | I33: 8.8 | J33: NORMAL | K33: =_xlfn.IFS('SERVICOS AUTPRO'!$J$25:$J$44="EXTRA 150%",((1)*2.5),'SERVICOS AUTPRO'!$J$25:$J$44="EXTRA 100%",((1)*2),'SERVICOS AUTPRO'!$J$25:$J$44="EXTRA 75%",((1)*1.75),'SERVICOS AUTPRO'!$J$25:$J$44="EXTRA 50%",((1)*1.5),'SERVICOS AUTPRO'!$J$25:$J$44="NORMAL",((1))) -> 1 | L33: =ServInt[[#This Row],[DIAS]]*ServInt[[#This Row],[PESSOAS]]*ServInt[[#This Row],[HORAS DIA]] -> 0 | M33: =(IF(ServInt[[#This Row],[CÓDIGO]]="","",LOOKUP(E33,BASE!A$4:A$125,BASE!G$4:G$125)))*ServInt[[#This Row],[HE CALC]] -> 0 | N33: =ServInt[[#This Row],[TOTAL HORAS]]*ServInt[[#This Row],[R$ / HORA]] -> 0 | O33: =BASE!$W$60 -> 0.66983974 | P33: =M33/O33 -> 0 | Q33: =N33/O33 -> 0 | S33: =(IF(E33="","",LOOKUP(E33,BASE!A$4:A$19,BASE!E$4:E$19)))*ServInt[[#This Row],[TOTAL HORAS]] -> 0 | T33: =IFERROR(ServInt[[#This Row],[TOTAL3]]*(RESUMO!$F$22/RESUMO!$F$14),0) -> 0 | W33: 9 | X33: Sistemas | Y33: Serviço | Z33: 0 | AA33: =LOOKUP(Z33,BASE!A$4:A$125,BASE!B$4:B$125) -> 0 | AD33: 8.8 | AE33: NORMAL | AF33: =_xlfn.IFS(ServExt[[#This Row],[TIPO H]]="EXTRA 150%",((1)*2.5),ServExt[[#This Row],[TIPO H]]="EXTRA 100%",((1)*2),ServExt[[#This Row],[TIPO H]]="EXTRA 75%",((1)*1.75),ServExt[[#This Row],[TIPO H]]="EXTRA 50%",((1)*1.5),ServExt[[#This Row],[TIPO H]]="NORMAL",((1))) -> 1 | AG33: =ServExt[[#This Row],[DIAS]]*ServExt[[#This Row],[PESSOAS]]*ServExt[[#This Row],[HORAS DIA]] -> 0 | AH33: =(IF(Z33="","",LOOKUP(Z33,BASE!A$4:A$125,BASE!H$4:H$125)))*ServExt[[#This Row],[HE CALC]] -> 0 | AI33: =ServExt[[#This Row],[TOTAL HORAS]]*ServExt[[#This Row],[R$ / HORA]] -> 0 | AJ33: =BASE!$W$60 -> 0.66983974 | AK33: =AH33/AJ33 -> 0 | AL33: =AI33/AJ33 -> 0 | AM33: =IF(OR(ServExt[[#This Row],[TIPO H]]="NORMAL",ServExt[[#This Row],[HORAS DIA]]>=8),ServExt[[#This Row],[PESSOAS]]*ServExt[[#This Row],[DIAS]]*2,0) -> 0 | AN33: =(IF(Z33="","",LOOKUP(Z33,BASE!A$4:A$19,BASE!E$4:E$19)))*ServExt[[#This Row],[TOTAL HORAS]] -> 0 | AO33: =IF(ServExt[[#This Row],[TIPO H]]="NORMAL",ServExt[[#This Row],[PESSOAS]],0) -> 0 | AP33: =IFERROR(ServExt[[#This Row],[TOTAL3]]*(RESUMO!$F$22/RESUMO!$F$14),0) -> 0 | AR33: 11 | AS33: Especialista em Computação I
B34: 10 | C34: Projetos | D34: Serviço | E34: 0 | F34: =LOOKUP('SERVICOS AUTPRO'!$E$25:$E$64,BASE!A$4:A$125,BASE!B$4:B$125) -> 0 | I34: 8.8 | J34: NORMAL | K34: =_xlfn.IFS('SERVICOS AUTPRO'!$J$25:$J$44="EXTRA 150%",((1)*2.5),'SERVICOS AUTPRO'!$J$25:$J$44="EXTRA 100%",((1)*2),'SERVICOS AUTPRO'!$J$25:$J$44="EXTRA 75%",((1)*1.75),'SERVICOS AUTPRO'!$J$25:$J$44="EXTRA 50%",((1)*1.5),'SERVICOS AUTPRO'!$J$25:$J$44="NORMAL",((1))) -> 1 | L34: =ServInt[[#This Row],[DIAS]]*ServInt[[#This Row],[PESSOAS]]*ServInt[[#This Row],[HORAS DIA]] -> 0 | M34: =(IF(ServInt[[#This Row],[CÓDIGO]]="","",LOOKUP(E34,BASE!A$4:A$125,BASE!G$4:G$125)))*ServInt[[#This Row],[HE CALC]] -> 0 | N34: =ServInt[[#This Row],[TOTAL HORAS]]*ServInt[[#This Row],[R$ / HORA]] -> 0 | O34: =BASE!$W$60 -> 0.66983974 | P34: =M34/O34 -> 0 | Q34: =N34/O34 -> 0 | S34: =(IF(E34="","",LOOKUP(E34,BASE!A$4:A$19,BASE!E$4:E$19)))*ServInt[[#This Row],[TOTAL HORAS]] -> 0 | T34: =IFERROR(ServInt[[#This Row],[TOTAL3]]*(RESUMO!$F$22/RESUMO!$F$14),0) -> 0 | W34: 10 | X34: Sistemas | Y34: Serviço | Z34: 0 | AA34: =LOOKUP(Z34,BASE!A$4:A$125,BASE!B$4:B$125) -> 0 | AD34: 8 | AE34: NORMAL | AF34: =_xlfn.IFS(ServExt[[#This Row],[TIPO H]]="EXTRA 150%",((1)*2.5),ServExt[[#This Row],[TIPO H]]="EXTRA 100%",((1)*2),ServExt[[#This Row],[TIPO H]]="EXTRA 75%",((1)*1.75),ServExt[[#This Row],[TIPO H]]="EXTRA 50%",((1)*1.5),ServExt[[#This Row],[TIPO H]]="NORMAL",((1))) -> 1 | AG34: =ServExt[[#This Row],[DIAS]]*ServExt[[#This Row],[PESSOAS]]*ServExt[[#This Row],[HORAS DIA]] -> 0 | AH34: =(IF(Z34="","",LOOKUP(Z34,BASE!A$4:A$125,BASE!H$4:H$125)))*ServExt[[#This Row],[HE CALC]] -> 0 | AI34: =ServExt[[#This Row],[TOTAL HORAS]]*ServExt[[#This Row],[R$ / HORA]] -> 0 | AJ34: =BASE!$W$60 -> 0.66983974 | AK34: =AH34/AJ34 -> 0 | AL34: =AI34/AJ34 -> 0 | AM34: =IF(OR(ServExt[[#This Row],[TIPO H]]="NORMAL",ServExt[[#This Row],[HORAS DIA]]>=8),ServExt[[#This Row],[PESSOAS]]*ServExt[[#This Row],[DIAS]]*2,0) -> 0 | AN34: =(IF(Z34="","",LOOKUP(Z34,BASE!A$4:A$19,BASE!E$4:E$19)))*ServExt[[#This Row],[TOTAL HORAS]] -> 0 | AO34: =IF(ServExt[[#This Row],[TIPO H]]="NORMAL",ServExt[[#This Row],[PESSOAS]],0) -> 0 | AP34: =IFERROR(ServExt[[#This Row],[TOTAL3]]*(RESUMO!$F$22/RESUMO!$F$14),0) -> 0 | AR34: 12 | AS34: Especialista em Computação II
B35: 11 | C35: Projetos | D35: Serviço | E35: 0 | F35: =LOOKUP('SERVICOS AUTPRO'!$E$25:$E$64,BASE!A$4:A$125,BASE!B$4:B$125) -> 0 | I35: 8.8 | J35: NORMAL | K35: =_xlfn.IFS('SERVICOS AUTPRO'!$J$25:$J$44="EXTRA 150%",((1)*2.5),'SERVICOS AUTPRO'!$J$25:$J$44="EXTRA 100%",((1)*2),'SERVICOS AUTPRO'!$J$25:$J$44="EXTRA 75%",((1)*1.75),'SERVICOS AUTPRO'!$J$25:$J$44="EXTRA 50%",((1)*1.5),'SERVICOS AUTPRO'!$J$25:$J$44="NORMAL",((1))) -> 1 | L35: =ServInt[[#This Row],[DIAS]]*ServInt[[#This Row],[PESSOAS]]*ServInt[[#This Row],[HORAS DIA]] -> 0 | M35: =(IF(ServInt[[#This Row],[CÓDIGO]]="","",LOOKUP(E35,BASE!A$4:A$125,BASE!G$4:G$125)))*ServInt[[#This Row],[HE CALC]] -> 0 | N35: =ServInt[[#This Row],[TOTAL HORAS]]*ServInt[[#This Row],[R$ / HORA]] -> 0 | O35: =BASE!$W$60 -> 0.66983974 | P35: =M35/O35 -> 0 | Q35: =N35/O35 -> 0 | S35: =(IF(E35="","",LOOKUP(E35,BASE!A$4:A$19,BASE!E$4:E$19)))*ServInt[[#This Row],[TOTAL HORAS]] -> 0 | T35: =IFERROR(ServInt[[#This Row],[TOTAL3]]*(RESUMO!$F$22/RESUMO!$F$14),0) -> 0 | W35: 11 | X35: Sistemas | Y35: Serviço | Z35: 0 | AA35: =LOOKUP(Z35,BASE!A$4:A$125,BASE!B$4:B$125) -> 0 | AD35: 8.8 | AE35: NORMAL | AF35: =_xlfn.IFS(ServExt[[#This Row],[TIPO H]]="EXTRA 150%",((1)*2.5),ServExt[[#This Row],[TIPO H]]="EXTRA 100%",((1)*2),ServExt[[#This Row],[TIPO H]]="EXTRA 75%",((1)*1.75),ServExt[[#This Row],[TIPO H]]="EXTRA 50%",((1)*1.5),ServExt[[#This Row],[TIPO H]]="NORMAL",((1))) -> 1 | AG35: =ServExt[[#This Row],[DIAS]]*ServExt[[#This Row],[PESSOAS]]*ServExt[[#This Row],[HORAS DIA]] -> 0 | AH35: =(IF(Z35="","",LOOKUP(Z35,BASE!A$4:A$125,BASE!H$4:H$125)))*ServExt[[#This Row],[HE CALC]] -> 0 | AI35: =ServExt[[#This Row],[TOTAL HORAS]]*ServExt[[#This Row],[R$ / HORA]] -> 0 | AJ35: =BASE!$W$60 -> 0.66983974 | AK35: =AH35/AJ35 -> 0 | AL35: =AI35/AJ35 -> 0 | AM35: =IF(OR(ServExt[[#This Row],[TIPO H]]="NORMAL",ServExt[[#This Row],[HORAS DIA]]>=8),ServExt[[#This Row],[PESSOAS]]*ServExt[[#This Row],[DIAS]]*2,0) -> 0 | AN35: =(IF(Z35="","",LOOKUP(Z35,BASE!A$4:A$19,BASE!E$4:E$19)))*ServExt[[#This Row],[TOTAL HORAS]] -> 0 | AO35: =IF(ServExt[[#This Row],[TIPO H]]="NORMAL",ServExt[[#This Row],[PESSOAS]],0) -> 0 | AP35: =IFERROR(ServExt[[#This Row],[TOTAL3]]*(RESUMO!$F$22/RESUMO!$F$14),0) -> 0 | AR35: 13 | AS35: Especialista Computação III
B36: 12 | C36: Projetos | D36: Serviço | E36: 0 | F36: =LOOKUP('SERVICOS AUTPRO'!$E$25:$E$64,BASE!A$4:A$125,BASE!B$4:B$125) -> 0 | I36: 8.8 | J36: NORMAL | K36: =_xlfn.IFS('SERVICOS AUTPRO'!$J$25:$J$44="EXTRA 150%",((1)*2.5),'SERVICOS AUTPRO'!$J$25:$J$44="EXTRA 100%",((1)*2),'SERVICOS AUTPRO'!$J$25:$J$44="EXTRA 75%",((1)*1.75),'SERVICOS AUTPRO'!$J$25:$J$44="EXTRA 50%",((1)*1.5),'SERVICOS AUTPRO'!$J$25:$J$44="NORMAL",((1))) -> 1 | L36: =ServInt[[#This Row],[DIAS]]*ServInt[[#This Row],[PESSOAS]]*ServInt[[#This Row],[HORAS DIA]] -> 0 | M36: =(IF(ServInt[[#This Row],[CÓDIGO]]="","",LOOKUP(E36,BASE!A$4:A$125,BASE!G$4:G$125)))*ServInt[[#This Row],[HE CALC]] -> 0 | N36: =ServInt[[#This Row],[TOTAL HORAS]]*ServInt[[#This Row],[R$ / HORA]] -> 0 | O36: =BASE!$W$60 -> 0.66983974 | P36: =M36/O36 -> 0 | Q36: =N36/O36 -> 0 | S36: =(IF(E36="","",LOOKUP(E36,BASE!A$4:A$19,BASE!E$4:E$19)))*ServInt[[#This Row],[TOTAL HORAS]] -> 0 | T36: =IFERROR(ServInt[[#This Row],[TOTAL3]]*(RESUMO!$F$22/RESUMO!$F$14),0) -> 0 | W36: 12 | X36: Sistemas | Y36: Serviço | Z36: 0 | AA36: =LOOKUP(Z36,BASE!A$4:A$125,BASE!B$4:B$125) -> 0 | AD36: 8.8 | AE36: NORMAL | AF36: =_xlfn.IFS(ServExt[[#This Row],[TIPO H]]="EXTRA 150%",((1)*2.5),ServExt[[#This Row],[TIPO H]]="EXTRA 100%",((1)*2),ServExt[[#This Row],[TIPO H]]="EXTRA 75%",((1)*1.75),ServExt[[#This Row],[TIPO H]]="EXTRA 50%",((1)*1.5),ServExt[[#This Row],[TIPO H]]="NORMAL",((1))) -> 1 | AG36: =ServExt[[#This Row],[DIAS]]*ServExt[[#This Row],[PESSOAS]]*ServExt[[#This Row],[HORAS DIA]] -> 0 | AH36: =(IF(Z36="","",LOOKUP(Z36,BASE!A$4:A$125,BASE!H$4:H$125)))*ServExt[[#This Row],[HE CALC]] -> 0 | AI36: =ServExt[[#This Row],[TOTAL HORAS]]*ServExt[[#This Row],[R$ / HORA]] -> 0 | AJ36: =BASE!$W$60 -> 0.66983974 | AK36: =AH36/AJ36 -> 0 | AL36: =AI36/AJ36 -> 0 | AM36: =IF(OR(ServExt[[#This Row],[TIPO H]]="NORMAL",ServExt[[#This Row],[HORAS DIA]]>=8),ServExt[[#This Row],[PESSOAS]]*ServExt[[#This Row],[DIAS]]*2,0) -> 0 | AN36: =(IF(Z36="","",LOOKUP(Z36,BASE!A$4:A$19,BASE!E$4:E$19)))*ServExt[[#This Row],[TOTAL HORAS]] -> 0 | AO36: =IF(ServExt[[#This Row],[TIPO H]]="NORMAL",ServExt[[#This Row],[PESSOAS]],0) -> 0 | AP36: =IFERROR(ServExt[[#This Row],[TOTAL3]]*(RESUMO!$F$22/RESUMO!$F$14),0) -> 0 | AR36: 14 | AS36: Especialista Computação IV
B37: 13 | C37: Projetos | D37: Serviço | E37: 0 | F37: =LOOKUP('SERVICOS AUTPRO'!$E$25:$E$64,BASE!A$4:A$125,BASE!B$4:B$125) -> 0 | I37: 8.8 | J37: NORMAL | K37: =_xlfn.IFS('SERVICOS AUTPRO'!$J$25:$J$44="EXTRA 150%",((1)*2.5),'SERVICOS AUTPRO'!$J$25:$J$44="EXTRA 100%",((1)*2),'SERVICOS AUTPRO'!$J$25:$J$44="EXTRA 75%",((1)*1.75),'SERVICOS AUTPRO'!$J$25:$J$44="EXTRA 50%",((1)*1.5),'SERVICOS AUTPRO'!$J$25:$J$44="NORMAL",((1))) -> 1 | L37: =ServInt[[#This Row],[DIAS]]*ServInt[[#This Row],[PESSOAS]]*ServInt[[#This Row],[HORAS DIA]] -> 0 | M37: =(IF(ServInt[[#This Row],[CÓDIGO]]="","",LOOKUP(E37,BASE!A$4:A$125,BASE!G$4:G$125)))*ServInt[[#This Row],[HE CALC]] -> 0 | N37: =ServInt[[#This Row],[TOTAL HORAS]]*ServInt[[#This Row],[R$ / HORA]] -> 0 | O37: =BASE!$W$60 -> 0.66983974 | P37: =M37/O37 -> 0 | Q37: =N37/O37 -> 0 | S37: =(IF(E37="","",LOOKUP(E37,BASE!A$4:A$19,BASE!E$4:E$19)))*ServInt[[#This Row],[TOTAL HORAS]] -> 0 | T37: =IFERROR(ServInt[[#This Row],[TOTAL3]]*(RESUMO!$F$22/RESUMO!$F$14),0) -> 0 | W37: 13 | X37: Sistemas | Y37: Serviço | Z37: 0 | AA37: =LOOKUP(Z37,BASE!A$4:A$125,BASE!B$4:B$125) -> 0 | AD37: 8.8 | AE37: NORMAL | AF37: =_xlfn.IFS(ServExt[[#This Row],[TIPO H]]="EXTRA 150%",((1)*2.5),ServExt[[#This Row],[TIPO H]]="EXTRA 100%",((1)*2),ServExt[[#This Row],[TIPO H]]="EXTRA 75%",((1)*1.75),ServExt[[#This Row],[TIPO H]]="EXTRA 50%",((1)*1.5),ServExt[[#This Row],[TIPO H]]="NORMAL",((1))) -> 1 | AG37: =ServExt[[#This Row],[DIAS]]*ServExt[[#This Row],[PESSOAS]]*ServExt[[#This Row],[HORAS DIA]] -> 0 | AH37: =(IF(Z37="","",LOOKUP(Z37,BASE!A$4:A$125,BASE!H$4:H$125)))*ServExt[[#This Row],[HE CALC]] -> 0 | AI37: =ServExt[[#This Row],[TOTAL HORAS]]*ServExt[[#This Row],[R$ / HORA]] -> 0 | AJ37: =BASE!$W$60 -> 0.66983974 | AK37: =AH37/AJ37 -> 0 | AL37: =AI37/AJ37 -> 0 | AM37: =IF(OR(ServExt[[#This Row],[TIPO H]]="NORMAL",ServExt[[#This Row],[HORAS DIA]]>=8),ServExt[[#This Row],[PESSOAS]]*ServExt[[#This Row],[DIAS]]*2,0) -> 0 | AN37: =(IF(Z37="","",LOOKUP(Z37,BASE!A$4:A$19,BASE!E$4:E$19)))*ServExt[[#This Row],[TOTAL HORAS]] -> 0 | AO37: =IF(ServExt[[#This Row],[TIPO H]]="NORMAL",ServExt[[#This Row],[PESSOAS]],0) -> 0 | AP37: =IFERROR(ServExt[[#This Row],[TOTAL3]]*(RESUMO!$F$22/RESUMO!$F$14),0) -> 0 | AR37: 15 | AS37: Especialista Computação V
B38: 14 | C38: Projetos | D38: Serviço | E38: 0 | F38: =LOOKUP('SERVICOS AUTPRO'!$E$25:$E$64,BASE!A$4:A$125,BASE!B$4:B$125) -> 0 | I38: 8.8 | J38: NORMAL | K38: =_xlfn.IFS('SERVICOS AUTPRO'!$J$25:$J$44="EXTRA 150%",((1)*2.5),'SERVICOS AUTPRO'!$J$25:$J$44="EXTRA 100%",((1)*2),'SERVICOS AUTPRO'!$J$25:$J$44="EXTRA 75%",((1)*1.75),'SERVICOS AUTPRO'!$J$25:$J$44="EXTRA 50%",((1)*1.5),'SERVICOS AUTPRO'!$J$25:$J$44="NORMAL",((1))) -> 1 | L38: =ServInt[[#This Row],[DIAS]]*ServInt[[#This Row],[PESSOAS]]*ServInt[[#This Row],[HORAS DIA]] -> 0 | M38: =(IF(ServInt[[#This Row],[CÓDIGO]]="","",LOOKUP(E38,BASE!A$4:A$125,BASE!G$4:G$125)))*ServInt[[#This Row],[HE CALC]] -> 0 | N38: =ServInt[[#This Row],[TOTAL HORAS]]*ServInt[[#This Row],[R$ / HORA]] -> 0 | O38: =BASE!$W$60 -> 0.66983974 | P38: =M38/O38 -> 0 | Q38: =N38/O38 -> 0 | S38: =(IF(E38="","",LOOKUP(E38,BASE!A$4:A$19,BASE!E$4:E$19)))*ServInt[[#This Row],[TOTAL HORAS]] -> 0 | T38: =IFERROR(ServInt[[#This Row],[TOTAL3]]*(RESUMO!$F$22/RESUMO!$F$14),0) -> 0 | W38: 14 | X38: Sistemas | Y38: Serviço | Z38: 0 | AA38: =LOOKUP(Z38,BASE!A$4:A$125,BASE!B$4:B$125) -> 0 | AD38: 8.8 | AE38: NORMAL | AF38: =_xlfn.IFS(ServExt[[#This Row],[TIPO H]]="EXTRA 150%",((1)*2.5),ServExt[[#This Row],[TIPO H]]="EXTRA 100%",((1)*2),ServExt[[#This Row],[TIPO H]]="EXTRA 75%",((1)*1.75),ServExt[[#This Row],[TIPO H]]="EXTRA 50%",((1)*1.5),ServExt[[#This Row],[TIPO H]]="NORMAL",((1))) -> 1 | AG38: =ServExt[[#This Row],[DIAS]]*ServExt[[#This Row],[PESSOAS]]*ServExt[[#This Row],[HORAS DIA]] -> 0 | AH38: =(IF(Z38="","",LOOKUP(Z38,BASE!A$4:A$125,BASE!H$4:H$125)))*ServExt[[#This Row],[HE CALC]] -> 0 | AI38: =ServExt[[#This Row],[TOTAL HORAS]]*ServExt[[#This Row],[R$ / HORA]] -> 0 | AJ38: =BASE!$W$60 -> 0.66983974 | AK38: =AH38/AJ38 -> 0 | AL38: =AI38/AJ38 -> 0 | AM38: =IF(OR(ServExt[[#This Row],[TIPO H]]="NORMAL",ServExt[[#This Row],[HORAS DIA]]>=8),ServExt[[#This Row],[PESSOAS]]*ServExt[[#This Row],[DIAS]]*2,0) -> 0 | AN38: =(IF(Z38="","",LOOKUP(Z38,BASE!A$4:A$19,BASE!E$4:E$19)))*ServExt[[#This Row],[TOTAL HORAS]] -> 0 | AO38: =IF(ServExt[[#This Row],[TIPO H]]="NORMAL",ServExt[[#This Row],[PESSOAS]],0) -> 0 | AP38: =IFERROR(ServExt[[#This Row],[TOTAL3]]*(RESUMO!$F$22/RESUMO!$F$14),0) -> 0 | AR38: 16 | AS38: Analista de Sistemas de Automação I
B39: 15 | C39: Projetos | D39: Serviço | E39: 0 | F39: =LOOKUP('SERVICOS AUTPRO'!$E$25:$E$64,BASE!A$4:A$125,BASE!B$4:B$125) -> 0 | I39: 8.8 | J39: NORMAL | K39: =_xlfn.IFS('SERVICOS AUTPRO'!$J$25:$J$44="EXTRA 150%",((1)*2.5),'SERVICOS AUTPRO'!$J$25:$J$44="EXTRA 100%",((1)*2),'SERVICOS AUTPRO'!$J$25:$J$44="EXTRA 75%",((1)*1.75),'SERVICOS AUTPRO'!$J$25:$J$44="EXTRA 50%",((1)*1.5),'SERVICOS AUTPRO'!$J$25:$J$44="NORMAL",((1))) -> 1 | L39: =ServInt[[#This Row],[DIAS]]*ServInt[[#This Row],[PESSOAS]]*ServInt[[#This Row],[HORAS DIA]] -> 0 | M39: =(IF(ServInt[[#This Row],[CÓDIGO]]="","",LOOKUP(E39,BASE!A$4:A$125,BASE!G$4:G$125)))*ServInt[[#This Row],[HE CALC]] -> 0 | N39: =ServInt[[#This Row],[TOTAL HORAS]]*ServInt[[#This Row],[R$ / HORA]] -> 0 | O39: =BASE!$W$60 -> 0.66983974 | P39: =M39/O39 -> 0 | Q39: =N39/O39 -> 0 | S39: =(IF(E39="","",LOOKUP(E39,BASE!A$4:A$19,BASE!E$4:E$19)))*ServInt[[#This Row],[TOTAL HORAS]] -> 0 | T39: =IFERROR(ServInt[[#This Row],[TOTAL3]]*(RESUMO!$F$22/RESUMO!$F$14),0) -> 0 | W39: 15 | X39: Sistemas | Y39: Serviço | Z39: 0 | AA39: =LOOKUP(Z39,BASE!A$4:A$125,BASE!B$4:B$125) -> 0 | AD39: 8.8 | AE39: NORMAL | AF39: =_xlfn.IFS(ServExt[[#This Row],[TIPO H]]="EXTRA 150%",((1)*2.5),ServExt[[#This Row],[TIPO H]]="EXTRA 100%",((1)*2),ServExt[[#This Row],[TIPO H]]="EXTRA 75%",((1)*1.75),ServExt[[#This Row],[TIPO H]]="EXTRA 50%",((1)*1.5),ServExt[[#This Row],[TIPO H]]="NORMAL",((1))) -> 1 | AG39: =ServExt[[#This Row],[DIAS]]*ServExt[[#This Row],[PESSOAS]]*ServExt[[#This Row],[HORAS DIA]] -> 0 | AH39: =(IF(Z39="","",LOOKUP(Z39,BASE!A$4:A$125,BASE!H$4:H$125)))*ServExt[[#This Row],[HE CALC]] -> 0 | AI39: =ServExt[[#This Row],[TOTAL HORAS]]*ServExt[[#This Row],[R$ / HORA]] -> 0 | AJ39: =BASE!$W$60 -> 0.66983974 | AK39: =AH39/AJ39 -> 0 | AL39: =AI39/AJ39 -> 0 | AM39: =IF(OR(ServExt[[#This Row],[TIPO H]]="NORMAL",ServExt[[#This Row],[HORAS DIA]]>=8),ServExt[[#This Row],[PESSOAS]]*ServExt[[#This Row],[DIAS]]*2,0) -> 0 | AN39: =(IF(Z39="","",LOOKUP(Z39,BASE!A$4:A$19,BASE!E$4:E$19)))*ServExt[[#This Row],[TOTAL HORAS]] -> 0 | AO39: =IF(ServExt[[#This Row],[TIPO H]]="NORMAL",ServExt[[#This Row],[PESSOAS]],0) -> 0 | AP39: =IFERROR(ServExt[[#This Row],[TOTAL3]]*(RESUMO!$F$22/RESUMO!$F$14),0) -> 0 | AR39: 17 | AS39: Analista de Sistemas de Automação II
B40: 16 | C40: Projetos | D40: Serviço | E40: 0 | F40: =LOOKUP('SERVICOS AUTPRO'!$E$25:$E$64,BASE!A$4:A$125,BASE!B$4:B$125) -> 0 | I40: 8.8 | J40: NORMAL | K40: =_xlfn.IFS('SERVICOS AUTPRO'!$J$25:$J$44="EXTRA 150%",((1)*2.5),'SERVICOS AUTPRO'!$J$25:$J$44="EXTRA 100%",((1)*2),'SERVICOS AUTPRO'!$J$25:$J$44="EXTRA 75%",((1)*1.75),'SERVICOS AUTPRO'!$J$25:$J$44="EXTRA 50%",((1)*1.5),'SERVICOS AUTPRO'!$J$25:$J$44="NORMAL",((1))) -> 1 | L40: =ServInt[[#This Row],[DIAS]]*ServInt[[#This Row],[PESSOAS]]*ServInt[[#This Row],[HORAS DIA]] -> 0 | M40: =(IF(ServInt[[#This Row],[CÓDIGO]]="","",LOOKUP(E40,BASE!A$4:A$125,BASE!G$4:G$125)))*ServInt[[#This Row],[HE CALC]] -> 0 | N40: =ServInt[[#This Row],[TOTAL HORAS]]*ServInt[[#This Row],[R$ / HORA]] -> 0 | O40: =BASE!$W$60 -> 0.66983974 | P40: =M40/O40 -> 0 | Q40: =N40/O40 -> 0 | S40: =(IF(E40="","",LOOKUP(E40,BASE!A$4:A$19,BASE!E$4:E$19)))*ServInt[[#This Row],[TOTAL HORAS]] -> 0 | T40: =IFERROR(ServInt[[#This Row],[TOTAL3]]*(RESUMO!$F$22/RESUMO!$F$14),0) -> 0 | W40: 16 | X40: Sistemas | Y40: Serviço | Z40: 0 | AA40: =LOOKUP(Z40,BASE!A$4:A$125,BASE!B$4:B$125) -> 0 | AD40: 8.8 | AE40: NORMAL | AF40: =_xlfn.IFS(ServExt[[#This Row],[TIPO H]]="EXTRA 150%",((1)*2.5),ServExt[[#This Row],[TIPO H]]="EXTRA 100%",((1)*2),ServExt[[#This Row],[TIPO H]]="EXTRA 75%",((1)*1.75),ServExt[[#This Row],[TIPO H]]="EXTRA 50%",((1)*1.5),ServExt[[#This Row],[TIPO H]]="NORMAL",((1))) -> 1 | AG40: =ServExt[[#This Row],[DIAS]]*ServExt[[#This Row],[PESSOAS]]*ServExt[[#This Row],[HORAS DIA]] -> 0 | AH40: =(IF(Z40="","",LOOKUP(Z40,BASE!A$4:A$125,BASE!H$4:H$125)))*ServExt[[#This Row],[HE CALC]] -> 0 | AI40: =ServExt[[#This Row],[TOTAL HORAS]]*ServExt[[#This Row],[R$ / HORA]] -> 0 | AJ40: =BASE!$W$60 -> 0.66983974 | AK40: =AH40/AJ40 -> 0 | AL40: =AI40/AJ40 -> 0 | AM40: =IF(OR(ServExt[[#This Row],[TIPO H]]="NORMAL",ServExt[[#This Row],[HORAS DIA]]>=8),ServExt[[#This Row],[PESSOAS]]*ServExt[[#This Row],[DIAS]]*2,0) -> 0 | AN40: =(IF(Z40="","",LOOKUP(Z40,BASE!A$4:A$19,BASE!E$4:E$19)))*ServExt[[#This Row],[TOTAL HORAS]] -> 0 | AO40: =IF(ServExt[[#This Row],[TIPO H]]="NORMAL",ServExt[[#This Row],[PESSOAS]],0) -> 0 | AP40: =IFERROR(ServExt[[#This Row],[TOTAL3]]*(RESUMO!$F$22/RESUMO!$F$14),0) -> 0 | AR40: 18 | AS40: Analista de Sistemas de Automação III
B41: 17 | C41: Projetos | D41: Serviço | E41: 0 | F41: =LOOKUP('SERVICOS AUTPRO'!$E$25:$E$64,BASE!A$4:A$125,BASE!B$4:B$125) -> 0 | I41: 8.8 | J41: NORMAL | K41: =_xlfn.IFS('SERVICOS AUTPRO'!$J$25:$J$44="EXTRA 150%",((1)*2.5),'SERVICOS AUTPRO'!$J$25:$J$44="EXTRA 100%",((1)*2),'SERVICOS AUTPRO'!$J$25:$J$44="EXTRA 75%",((1)*1.75),'SERVICOS AUTPRO'!$J$25:$J$44="EXTRA 50%",((1)*1.5),'SERVICOS AUTPRO'!$J$25:$J$44="NORMAL",((1))) -> 1 | L41: =ServInt[[#This Row],[DIAS]]*ServInt[[#This Row],[PESSOAS]]*ServInt[[#This Row],[HORAS DIA]] -> 0 | M41: =(IF(ServInt[[#This Row],[CÓDIGO]]="","",LOOKUP(E41,BASE!A$4:A$125,BASE!G$4:G$125)))*ServInt[[#This Row],[HE CALC]] -> 0 | N41: =ServInt[[#This Row],[TOTAL HORAS]]*ServInt[[#This Row],[R$ / HORA]] -> 0 | O41: =BASE!$W$60 -> 0.66983974 | P41: =M41/O41 -> 0 | Q41: =N41/O41 -> 0 | S41: =(IF(E41="","",LOOKUP(E41,BASE!A$4:A$19,BASE!E$4:E$19)))*ServInt[[#This Row],[TOTAL HORAS]] -> 0 | T41: =IFERROR(ServInt[[#This Row],[TOTAL3]]*(RESUMO!$F$22/RESUMO!$F$14),0) -> 0 | W41: 17 | X41: Sistemas | Y41: Serviço | Z41: 0 | AA41: =LOOKUP(Z41,BASE!A$4:A$125,BASE!B$4:B$125) -> 0 | AD41: 8.8 | AE41: NORMAL | AF41: =_xlfn.IFS(ServExt[[#This Row],[TIPO H]]="EXTRA 150%",((1)*2.5),ServExt[[#This Row],[TIPO H]]="EXTRA 100%",((1)*2),ServExt[[#This Row],[TIPO H]]="EXTRA 75%",((1)*1.75),ServExt[[#This Row],[TIPO H]]="EXTRA 50%",((1)*1.5),ServExt[[#This Row],[TIPO H]]="NORMAL",((1))) -> 1 | AG41: =ServExt[[#This Row],[DIAS]]*ServExt[[#This Row],[PESSOAS]]*ServExt[[#This Row],[HORAS DIA]] -> 0 | AH41: =(IF(Z41="","",LOOKUP(Z41,BASE!A$4:A$125,BASE!H$4:H$125)))*ServExt[[#This Row],[HE CALC]] -> 0 | AI41: =ServExt[[#This Row],[TOTAL HORAS]]*ServExt[[#This Row],[R$ / HORA]] -> 0 | AJ41: =BASE!$W$60 -> 0.66983974 | AK41: =AH41/AJ41 -> 0 | AL41: =AI41/AJ41 -> 0 | AM41: =IF(OR(ServExt[[#This Row],[TIPO H]]="NORMAL",ServExt[[#This Row],[HORAS DIA]]>=8),ServExt[[#This Row],[PESSOAS]]*ServExt[[#This Row],[DIAS]]*2,0) -> 0 | AN41: =(IF(Z41="","",LOOKUP(Z41,BASE!A$4:A$19,BASE!E$4:E$19)))*ServExt[[#This Row],[TOTAL HORAS]] -> 0 | AO41: =IF(ServExt[[#This Row],[TIPO H]]="NORMAL",ServExt[[#This Row],[PESSOAS]],0) -> 0 | AP41: =IFERROR(ServExt[[#This Row],[TOTAL3]]*(RESUMO!$F$22/RESUMO!$F$14),0) -> 0 | AR41: 19 | AS41: Analista de Sistemas de Automação IV
B42: 18 | C42: Projetos | D42: Serviço | E42: 0 | F42: =LOOKUP('SERVICOS AUTPRO'!$E$25:$E$64,BASE!A$4:A$125,BASE!B$4:B$125) -> 0 | I42: 8.8 | J42: NORMAL | K42: =_xlfn.IFS('SERVICOS AUTPRO'!$J$25:$J$44="EXTRA 150%",((1)*2.5),'SERVICOS AUTPRO'!$J$25:$J$44="EXTRA 100%",((1)*2),'SERVICOS AUTPRO'!$J$25:$J$44="EXTRA 75%",((1)*1.75),'SERVICOS AUTPRO'!$J$25:$J$44="EXTRA 50%",((1)*1.5),'SERVICOS AUTPRO'!$J$25:$J$44="NORMAL",((1))) -> 1 | L42: =ServInt[[#This Row],[DIAS]]*ServInt[[#This Row],[PESSOAS]]*ServInt[[#This Row],[HORAS DIA]] -> 0 | M42: =(IF(ServInt[[#This Row],[CÓDIGO]]="","",LOOKUP(E42,BASE!A$4:A$125,BASE!G$4:G$125)))*ServInt[[#This Row],[HE CALC]] -> 0 | N42: =ServInt[[#This Row],[TOTAL HORAS]]*ServInt[[#This Row],[R$ / HORA]] -> 0 | O42: =BASE!$W$60 -> 0.66983974 | P42: =M42/O42 -> 0 | Q42: =N42/O42 -> 0 | S42: =(IF(E42="","",LOOKUP(E42,BASE!A$4:A$19,BASE!E$4:E$19)))*ServInt[[#This Row],[TOTAL HORAS]] -> 0 | T42: =IFERROR(ServInt[[#This Row],[TOTAL3]]*(RESUMO!$F$22/RESUMO!$F$14),0) -> 0 | W42: 18 | X42: Sistemas | Y42: Serviço | Z42: 0 | AA42: =LOOKUP(Z42,BASE!A$4:A$125,BASE!B$4:B$125) -> 0 | AD42: 8.8 | AE42: NORMAL | AF42: =_xlfn.IFS(ServExt[[#This Row],[TIPO H]]="EXTRA 150%",((1)*2.5),ServExt[[#This Row],[TIPO H]]="EXTRA 100%",((1)*2),ServExt[[#This Row],[TIPO H]]="EXTRA 75%",((1)*1.75),ServExt[[#This Row],[TIPO H]]="EXTRA 50%",((1)*1.5),ServExt[[#This Row],[TIPO H]]="NORMAL",((1))) -> 1 | AG42: =ServExt[[#This Row],[DIAS]]*ServExt[[#This Row],[PESSOAS]]*ServExt[[#This Row],[HORAS DIA]] -> 0 | AH42: =(IF(Z42="","",LOOKUP(Z42,BASE!A$4:A$125,BASE!H$4:H$125)))*ServExt[[#This Row],[HE CALC]] -> 0 | AI42: =ServExt[[#This Row],[TOTAL HORAS]]*ServExt[[#This Row],[R$ / HORA]] -> 0 | AJ42: =BASE!$W$60 -> 0.66983974 | AK42: =AH42/AJ42 -> 0 | AL42: =AI42/AJ42 -> 0 | AM42: =IF(OR(ServExt[[#This Row],[TIPO H]]="NORMAL",ServExt[[#This Row],[HORAS DIA]]>=8),ServExt[[#This Row],[PESSOAS]]*ServExt[[#This Row],[DIAS]]*2,0) -> 0 | AN42: =(IF(Z42="","",LOOKUP(Z42,BASE!A$4:A$19,BASE!E$4:E$19)))*ServExt[[#This Row],[TOTAL HORAS]] -> 0 | AO42: =IF(ServExt[[#This Row],[TIPO H]]="NORMAL",ServExt[[#This Row],[PESSOAS]],0) -> 0 | AP42: =IFERROR(ServExt[[#This Row],[TOTAL3]]*(RESUMO!$F$22/RESUMO!$F$14),0) -> 0 | AR42: 20 | AS42: Analista de Sistemas de Automação V
B43: 19 | C43: Projetos | D43: Serviço | E43: 0 | F43: =LOOKUP('SERVICOS AUTPRO'!$E$25:$E$64,BASE!A$4:A$125,BASE!B$4:B$125) -> 0 | I43: 8.8 | J43: NORMAL | K43: =_xlfn.IFS('SERVICOS AUTPRO'!$J$25:$J$44="EXTRA 150%",((1)*2.5),'SERVICOS AUTPRO'!$J$25:$J$44="EXTRA 100%",((1)*2),'SERVICOS AUTPRO'!$J$25:$J$44="EXTRA 75%",((1)*1.75),'SERVICOS AUTPRO'!$J$25:$J$44="EXTRA 50%",((1)*1.5),'SERVICOS AUTPRO'!$J$25:$J$44="NORMAL",((1))) -> 1 | L43: =ServInt[[#This Row],[DIAS]]*ServInt[[#This Row],[PESSOAS]]*ServInt[[#This Row],[HORAS DIA]] -> 0 | M43: =(IF(ServInt[[#This Row],[CÓDIGO]]="","",LOOKUP(E43,BASE!A$4:A$125,BASE!G$4:G$125)))*ServInt[[#This Row],[HE CALC]] -> 0 | N43: =ServInt[[#This Row],[TOTAL HORAS]]*ServInt[[#This Row],[R$ / HORA]] -> 0 | O43: =BASE!$W$60 -> 0.66983974 | P43: =M43/O43 -> 0 | Q43: =N43/O43 -> 0 | S43: =(IF(E43="","",LOOKUP(E43,BASE!A$4:A$19,BASE!E$4:E$19)))*ServInt[[#This Row],[TOTAL HORAS]] -> 0 | T43: =IFERROR(ServInt[[#This Row],[TOTAL3]]*(RESUMO!$F$22/RESUMO!$F$14),0) -> 0 | W43: 19 | X43: Sistemas | Y43: Serviço | Z43: 0 | AA43: =LOOKUP(Z43,BASE!A$4:A$125,BASE!B$4:B$125) -> 0 | AB43: 0 | AD43: 8.8 | AE43: NORMAL | AF43: =_xlfn.IFS(ServExt[[#This Row],[TIPO H]]="EXTRA 150%",((1)*2.5),ServExt[[#This Row],[TIPO H]]="EXTRA 100%",((1)*2),ServExt[[#This Row],[TIPO H]]="EXTRA 75%",((1)*1.75),ServExt[[#This Row],[TIPO H]]="EXTRA 50%",((1)*1.5),ServExt[[#This Row],[TIPO H]]="NORMAL",((1))) -> 1 | AG43: =ServExt[[#This Row],[DIAS]]*ServExt[[#This Row],[PESSOAS]]*ServExt[[#This Row],[HORAS DIA]] -> 0 | AH43: =(IF(Z43="","",LOOKUP(Z43,BASE!A$4:A$125,BASE!H$4:H$125)))*ServExt[[#This Row],[HE CALC]] -> 0 | AI43: =ServExt[[#This Row],[TOTAL HORAS]]*ServExt[[#This Row],[R$ / HORA]] -> 0 | AJ43: =BASE!$W$60 -> 0.66983974 | AK43: =AH43/AJ43 -> 0 | AL43: =AI43/AJ43 -> 0 | AM43: =IF(OR(ServExt[[#This Row],[TIPO H]]="NORMAL",ServExt[[#This Row],[HORAS DIA]]>=8),ServExt[[#This Row],[PESSOAS]]*ServExt[[#This Row],[DIAS]]*2,0) -> 0 | AN43: =(IF(Z43="","",LOOKUP(Z43,BASE!A$4:A$19,BASE!E$4:E$19)))*ServExt[[#This Row],[TOTAL HORAS]] -> 0 | AO43: =IF(ServExt[[#This Row],[TIPO H]]="NORMAL",ServExt[[#This Row],[PESSOAS]],0) -> 0 | AP43: =IFERROR(ServExt[[#This Row],[TOTAL3]]*(RESUMO!$F$22/RESUMO!$F$14),0) -> 0 | AR43: 21 | AS43: Desenhista Projetista I
B44: 20 | C44: Projetos | D44: Serviço | E44: 0 | F44: =LOOKUP('SERVICOS AUTPRO'!$E$25:$E$64,BASE!A$4:A$125,BASE!B$4:B$125) -> 0 | I44: 8.8 | J44: NORMAL | K44: =_xlfn.IFS('SERVICOS AUTPRO'!$J$25:$J$44="EXTRA 150%",((1)*2.5),'SERVICOS AUTPRO'!$J$25:$J$44="EXTRA 100%",((1)*2),'SERVICOS AUTPRO'!$J$25:$J$44="EXTRA 75%",((1)*1.75),'SERVICOS AUTPRO'!$J$25:$J$44="EXTRA 50%",((1)*1.5),'SERVICOS AUTPRO'!$J$25:$J$44="NORMAL",((1))) -> 1 | L44: =ServInt[[#This Row],[DIAS]]*ServInt[[#This Row],[PESSOAS]]*ServInt[[#This Row],[HORAS DIA]] -> 0 | M44: =(IF(ServInt[[#This Row],[CÓDIGO]]="","",LOOKUP(E44,BASE!A$4:A$125,BASE!G$4:G$125)))*ServInt[[#This Row],[HE CALC]] -> 0 | N44: =ServInt[[#This Row],[TOTAL HORAS]]*ServInt[[#This Row],[R$ / HORA]] -> 0 | O44: =BASE!$W$60 -> 0.66983974 | P44: =M44/O44 -> 0 | Q44: =N44/O44 -> 0 | S44: =(IF(E44="","",LOOKUP(E44,BASE!A$4:A$19,BASE!E$4:E$19)))*ServInt[[#This Row],[TOTAL HORAS]] -> 0 | T44: =IFERROR(ServInt[[#This Row],[TOTAL3]]*(RESUMO!$F$22/RESUMO!$F$14),0) -> 0 | W44: 20 | X44: Sistemas | Y44: Serviço | Z44: 0 | AA44: =LOOKUP(Z44,BASE!A$4:A$125,BASE!B$4:B$125) -> 0 | AB44: 0 | AD44: 8.8 | AE44: NORMAL | AF44: =_xlfn.IFS(ServExt[[#This Row],[TIPO H]]="EXTRA 150%",((1)*2.5),ServExt[[#This Row],[TIPO H]]="EXTRA 100%",((1)*2),ServExt[[#This Row],[TIPO H]]="EXTRA 75%",((1)*1.75),ServExt[[#This Row],[TIPO H]]="EXTRA 50%",((1)*1.5),ServExt[[#This Row],[TIPO H]]="NORMAL",((1))) -> 1 | AG44: =ServExt[[#This Row],[DIAS]]*ServExt[[#This Row],[PESSOAS]]*ServExt[[#This Row],[HORAS DIA]] -> 0 | AH44: =(IF(Z44="","",LOOKUP(Z44,BASE!A$4:A$125,BASE!H$4:H$125)))*ServExt[[#This Row],[HE CALC]] -> 0 | AI44: =ServExt[[#This Row],[TOTAL HORAS]]*ServExt[[#This Row],[R$ / HORA]] -> 0 | AJ44: =BASE!$W$60 -> 0.66983974 | AK44: =AH44/AJ44 -> 0 | AL44: =AI44/AJ44 -> 0 | AM44: =IF(OR(ServExt[[#This Row],[TIPO H]]="NORMAL",ServExt[[#This Row],[HORAS DIA]]>=8),ServExt[[#This Row],[PESSOAS]]*ServExt[[#This Row],[DIAS]]*2,0) -> 0 | AN44: =(IF(Z44="","",LOOKUP(Z44,BASE!A$4:A$19,BASE!E$4:E$19)))*ServExt[[#This Row],[TOTAL HORAS]] -> 0 | AO44: =IF(ServExt[[#This Row],[TIPO H]]="NORMAL",ServExt[[#This Row],[PESSOAS]],0) -> 0 | AP44: =IFERROR(ServExt[[#This Row],[TOTAL3]]*(RESUMO!$F$22/RESUMO!$F$14),0) -> 0 | AR44: 22 | AS44: Desenhista Projetista II
B45: 21 | C45: Projetos | D45: Serviço | E45: 0 | F45: =LOOKUP('SERVICOS AUTPRO'!$E$25:$E$64,BASE!A$4:A$125,BASE!B$4:B$125) -> 0 | I45: 8.8 | J45: NORMAL | K45: =_xlfn.IFS('SERVICOS AUTPRO'!$J$25:$J$64="EXTRA 150%",((1)*2.5),'SERVICOS AUTPRO'!$J$25:$J$64="EXTRA 100%",((1)*2),'SERVICOS AUTPRO'!$J$25:$J$64="EXTRA 75%",((1)*1.75),'SERVICOS AUTPRO'!$J$25:$J$64="EXTRA 50%",((1)*1.5),'SERVICOS AUTPRO'!$J$25:$J$64="NORMAL",((1))) -> 1 | L45: =ServInt[[#This Row],[DIAS]]*ServInt[[#This Row],[PESSOAS]]*ServInt[[#This Row],[HORAS DIA]] -> 0 | M45: =(IF(ServInt[[#This Row],[CÓDIGO]]="","",LOOKUP(E45,BASE!A$4:A$125,BASE!G$4:G$125)))*ServInt[[#This Row],[HE CALC]] -> 0 | N45: =ServInt[[#This Row],[TOTAL HORAS]]*ServInt[[#This Row],[R$ / HORA]] -> 0 | O45: =BASE!$W$60 -> 0.66983974 | P45: =M45/O45 -> 0 | Q45: =N45/O45 -> 0 | S45: =(IF(E45="","",LOOKUP(E45,BASE!A$4:A$19,BASE!E$4:E$19)))*ServInt[[#This Row],[TOTAL HORAS]] -> 0 | T45: =IFERROR(ServInt[[#This Row],[TOTAL3]]*(RESUMO!$F$22/RESUMO!$F$14),0) -> 0 | W45: 21 | X45: Sistemas | Y45: Serviço | Z45: 0 | AA45: =LOOKUP(Z45,BASE!A$4:A$125,BASE!B$4:B$125) -> 0 | AD45: 8.8 | AE45: NORMAL | AF45: =_xlfn.IFS(ServExt[[#This Row],[TIPO H]]="EXTRA 150%",((1)*2.5),ServExt[[#This Row],[TIPO H]]="EXTRA 100%",((1)*2),ServExt[[#This Row],[TIPO H]]="EXTRA 75%",((1)*1.75),ServExt[[#This Row],[TIPO H]]="EXTRA 50%",((1)*1.5),ServExt[[#This Row],[TIPO H]]="NORMAL",((1))) -> 1 | AG45: =ServExt[[#This Row],[DIAS]]*ServExt[[#This Row],[PESSOAS]]*ServExt[[#This Row],[HORAS DIA]] -> 0 | AH45: =(IF(Z45="","",LOOKUP(Z45,BASE!A$4:A$125,BASE!H$4:H$125)))*ServExt[[#This Row],[HE CALC]] -> 0 | AI45: =ServExt[[#This Row],[TOTAL HORAS]]*ServExt[[#This Row],[R$ / HORA]] -> 0 | AJ45: =BASE!$W$60 -> 0.66983974 | AK45: =AH45/AJ45 -> 0 | AL45: =AI45/AJ45 -> 0 | AM45: =IF(OR(ServExt[[#This Row],[TIPO H]]="NORMAL",ServExt[[#This Row],[HORAS DIA]]>=8),ServExt[[#This Row],[PESSOAS]]*ServExt[[#This Row],[DIAS]]*2,0) -> 0 | AN45: =(IF(Z45="","",LOOKUP(Z45,BASE!A$4:A$19,BASE!E$4:E$19)))*ServExt[[#This Row],[TOTAL HORAS]] -> 0 | AO45: =IF(ServExt[[#This Row],[TIPO H]]="NORMAL",ServExt[[#This Row],[PESSOAS]],0) -> 0 | AP45: =IFERROR(ServExt[[#This Row],[TOTAL3]]*(RESUMO!$F$22/RESUMO!$F$14),0) -> 0 | AR45: 23 | AS45: Desenhista Projetista III
